Workbook

Sheet Data
A1: Ville
A2: Département
A3: County
A4: 45658
A5: 45659
A6: 45660
A7: 45661
A8: 45662
A9: 45663
A10: 45664
A11: 45665
A12: 45666
A13: 45667
A14: 45668
A15: 45669
... A93: 45747

Sheet Test
A1: Département | C1: =Data!I3 -> 0
A2: Ville | B2: Seuil (143°J) | C2: =_xlfn.CONCAT(Data!I1," (",Data!I2,")") -> #NAME? | D2: Caderousse (84) - Base 0°
A3: 46023 | B3: 143 | C3: =IF(Data!I4-4>0,Data!I4-4,0) -> 0 | D3: =IF(Data!I4>0,Data!I4,0) -> 0
A4: 46024 | B4: 143 | C4: =IF(Data!I5-4>0,Data!I5-4,0)+C3 -> 0 | D4: =IF(Data!I5>0,Data!I5,0)+D3 -> 0
A5: 46025 | B5: 143 | C5: =IF(Data!I6-4>0,Data!I6-4,0)+C4 -> 0 | D5: =IF(Data!I6>0,Data!I6,0)+D4 -> 0
A6: 46026 | B6: 143 | C6: =IF(Data!I7-4>0,Data!I7-4,0)+C5 -> 0 | D6: =IF(Data!I7>0,Data!I7,0)+D5 -> 0
A7: 46027 | B7: 143 | C7: =IF(Data!I8-4>0,Data!I8-4,0)+C6 -> 0 | D7: =IF(Data!I8>0,Data!I8,0)+D6 -> 0
A8: 46028 | B8: 143 | C8: =IF(Data!I9-4>0,Data!I9-4,0)+C7 -> 0 | D8: =IF(Data!I9>0,Data!I9,0)+D7 -> 0
A9: 46029 | B9: 143 | C9: =IF(Data!I10-4>0,Data!I10-4,0)+C8 -> 0 | D9: =IF(Data!I10>0,Data!I10,0)+D8 -> 0
A10: 46030 | B10: 143 | C10: =IF(Data!I11-4>0,Data!I11-4,0)+C9 -> 0 | D10: =IF(Data!I11>0,Data!I11,0)+D9 -> 0
A11: 46031 | B11: 143 | C11: =IF(Data!I12-4>0,Data!I12-4,0)+C10 -> 0 | D11: =IF(Data!I12>0,Data!I12,0)+D10 -> 0
A12: 46032 | B12: 143 | C12: =IF(Data!I13-4>0,Data!I13-4,0)+C11 -> 0 | D12: =IF(Data!I13>0,Data!I13,0)+D11 -> 0
A13: 46033 | B13: 143 | C13: =IF(Data!I14-4>0,Data!I14-4,0)+C12 -> 0 | D13: =IF(Data!I14>0,Data!I14,0)+D12 -> 0
A14: 46034 | B14: 143 | C14: =IF(Data!I15-4>0,Data!I15-4,0)+C13 -> 0 | D14: =IF(Data!I15>0,Data!I15,0)+D13 -> 0
A15: 46035 | B15: 143 | C15: =IF(Data!I16-4>0,Data!I16-4,0)+C14 -> 0 | D15: =IF(Data!I16>0,Data!I16,0)+D14 -> 0
... A92: 46112 | B92: 143 | C92: =IF(Data!I93-4>0,Data!I93-4,0)+C91 -> 0 | D92: =IF(Data!I93>0,Data!I93,0)+D91 -> 0

Sheet Ouest
J1: Département | L1: =Data!B3 -> 0 | M1: =Data!C3 -> 0 | N1: =Data!D3 -> 0 | O1: =Data!E3 -> 0 | P1: =Data!F3 -> 0 | Q1: =Data!G3 -> 0 | R1: =Data!H3 -> 0 | S1: =Data!I3 -> 0 | T1: =L1 -> 0 | U1: =M1 -> 0 | V1: =N1 -> 0 | W1: =O1 -> 0 | X1: =P1 -> 0 | Y1: =Q1 -> 0 | Z1: =R1 -> 0 | AA1: =S1 -> 0
J2: Ville | K2: Seuil (143°J) | L2: =_xlfn.CONCAT(Data!B1," (",Data!B2,")") -> #NAME? | M2: =_xlfn.CONCAT(Data!C1," (",Data!C2,")") -> #NAME? | N2: =_xlfn.CONCAT(Data!D1," (",Data!D2,")") -> #NAME? | O2: =_xlfn.CONCAT(Data!E1," (",Data!E2,")") -> #NAME? | P2: =_xlfn.CONCAT(Data!F1," (",Data!F2,")") -> #NAME? | Q2: =_xlfn.CONCAT(Data!G1," (",Data!G2,")") -> #NAME? | R2: =_xlfn.CONCAT(Data!H1," (",Data!H2,")") -> #NAME? | S2: =_xlfn.CONCAT(Data!I1," (",Data!I2,")") -> #NAME? | T2: =L2 -> #NAME? | U2: =M2 -> #NAME? | V2: =N2 -> #NAME? | W2: =O2 -> #NAME? | X2: =P2 -> #NAME? | Y2: =Q2 -> #NAME? | Z2: =R2 -> #NAME? | AA2: =S2 -> #NAME?
J3: 46023 | K3: 143 | L3: =IF(Data!B4-4>0,Data!B4-4,0) -> 0 | M3: =IF(Data!C4-4>0,Data!C4-4,0) -> 0 | N3: =IF(Data!D4-4>0,Data!D4-4,0) -> 0 | O3: =IF(Data!E4-4>0,Data!E4-4,0) -> 0 | P3: =IF(Data!F4-4>0,Data!F4-4,0) -> 0 | Q3: =IF(Data!G4-4>0,Data!G4-4,0) -> 0 | R3: =IF(Data!H4-4>0,Data!H4-4,0) -> 0 | S3: =IF(Data!I4-4>0,Data!I4-4,0) -> 0 | T3: =IF(Data!B4>0,Data!B4,0) -> 0 | U3: =IF(Data!C4>0,Data!C4,0) -> 0 | V3: =IF(Data!D4>0,Data!D4,0) -> 0 | W3: =IF(Data!E4>0,Data!E4,0) -> 0 | X3: =IF(Data!F4>0,Data!F4,0) -> 0 | Y3: =IF(Data!G4>0,Data!G4,0) -> 0 | Z3: =IF(Data!H4>0,Data!H4,0) -> 0 | AA3: =IF(Data!I4>0,Data!I4,0) -> 0
J4: 46024 | K4: 143 | L4: =IF(Data!B5-4>0,Data!B5-4,0)+L3 -> 0 | M4: =IF(Data!C5-4>0,Data!C5-4,0)+M3 -> 0 | N4: =IF(Data!D5-4>0,Data!D5-4,0)+N3 -> 0 | O4: =IF(Data!E5-4>0,Data!E5-4,0)+O3 -> 0 | P4: =IF(Data!F5-4>0,Data!F5-4,0)+P3 -> 0 | Q4: =IF(Data!G5-4>0,Data!G5-4,0)+Q3 -> 0 | R4: =IF(Data!H5-4>0,Data!H5-4,0)+R3 -> 0 | S4: =IF(Data!I5-4>0,Data!I5-4,0)+S3 -> 0 | T4: =IF(Data!B5>0,Data!B5,0)+T3 -> 0 | U4: =IF(Data!C5>0,Data!C5,0)+U3 -> 0 | V4: =IF(Data!D5>0,Data!D5,0)+V3 -> 0 | W4: =IF(Data!E5>0,Data!E5,0)+W3 -> 0 | X4: =IF(Data!F5>0,Data!F5,0)+X3 -> 0 | Y4: =IF(Data!G5>0,Data!G5,0)+Y3 -> 0 | Z4: =IF(Data!H5>0,Data!H5,0)+Z3 -> 0 | AA4: =IF(Data!I5>0,Data!I5,0)+AA3 -> 0
J5: 46025 | K5: 143 | L5: =IF(Data!B6-4>0,Data!B6-4,0)+L4 -> 0 | M5: =IF(Data!C6-4>0,Data!C6-4,0)+M4 -> 0 | N5: =IF(Data!D6-4>0,Data!D6-4,0)+N4 -> 0 | O5: =IF(Data!E6-4>0,Data!E6-4,0)+O4 -> 0 | P5: =IF(Data!F6-4>0,Data!F6-4,0)+P4 -> 0 | Q5: =IF(Data!G6-4>0,Data!G6-4,0)+Q4 -> 0 | R5: =IF(Data!H6-4>0,Data!H6-4,0)+R4 -> 0 | S5: =IF(Data!I6-4>0,Data!I6-4,0)+S4 -> 0 | T5: =IF(Data!B6>0,Data!B6,0)+T4 -> 0 | U5: =IF(Data!C6>0,Data!C6,0)+U4 -> 0 | V5: =IF(Data!D6>0,Data!D6,0)+V4 -> 0 | W5: =IF(Data!E6>0,Data!E6,0)+W4 -> 0 | X5: =IF(Data!F6>0,Data!F6,0)+X4 -> 0 | Y5: =IF(Data!G6>0,Data!G6,0)+Y4 -> 0 | Z5: =IF(Data!H6>0,Data!H6,0)+Z4 -> 0 | AA5: =IF(Data!I6>0,Data!I6,0)+AA4 -> 0
J6: 46026 | K6: 143 | L6: =IF(Data!B7-4>0,Data!B7-4,0)+L5 -> 0 | M6: =IF(Data!C7-4>0,Data!C7-4,0)+M5 -> 0 | N6: =IF(Data!D7-4>0,Data!D7-4,0)+N5 -> 0 | O6: =IF(Data!E7-4>0,Data!E7-4,0)+O5 -> 0 | P6: =IF(Data!F7-4>0,Data!F7-4,0)+P5 -> 0 | Q6: =IF(Data!G7-4>0,Data!G7-4,0)+Q5 -> 0 | R6: =IF(Data!H7-4>0,Data!H7-4,0)+R5 -> 0 | S6: =IF(Data!I7-4>0,Data!I7-4,0)+S5 -> 0 | T6: =IF(Data!B7>0,Data!B7,0)+T5 -> 0 | U6: =IF(Data!C7>0,Data!C7,0)+U5 -> 0 | V6: =IF(Data!D7>0,Data!D7,0)+V5 -> 0 | W6: =IF(Data!E7>0,Data!E7,0)+W5 -> 0 | X6: =IF(Data!F7>0,Data!F7,0)+X5 -> 0 | Y6: =IF(Data!G7>0,Data!G7,0)+Y5 -> 0 | Z6: =IF(Data!H7>0,Data!H7,0)+Z5 -> 0 | AA6: =IF(Data!I7>0,Data!I7,0)+AA5 -> 0
J7: 46027 | K7: 143 | L7: =IF(Data!B8-4>0,Data!B8-4,0)+L6 -> 0 | M7: =IF(Data!C8-4>0,Data!C8-4,0)+M6 -> 0 | N7: =IF(Data!D8-4>0,Data!D8-4,0)+N6 -> 0 | O7: =IF(Data!E8-4>0,Data!E8-4,0)+O6 -> 0 | P7: =IF(Data!F8-4>0,Data!F8-4,0)+P6 -> 0 | Q7: =IF(Data!G8-4>0,Data!G8-4,0)+Q6 -> 0 | R7: =IF(Data!H8-4>0,Data!H8-4,0)+R6 -> 0 | S7: =IF(Data!I8-4>0,Data!I8-4,0)+S6 -> 0 | T7: =IF(Data!B8>0,Data!B8,0)+T6 -> 0 | U7: =IF(Data!C8>0,Data!C8,0)+U6 -> 0 | V7: =IF(Data!D8>0,Data!D8,0)+V6 -> 0 | W7: =IF(Data!E8>0,Data!E8,0)+W6 -> 0 | X7: =IF(Data!F8>0,Data!F8,0)+X6 -> 0 | Y7: =IF(Data!G8>0,Data!G8,0)+Y6 -> 0 | Z7: =IF(Data!H8>0,Data!H8,0)+Z6 -> 0 | AA7: =IF(Data!I8>0,Data!I8,0)+AA6 -> 0
J8: 46028 | K8: 143 | L8: =IF(Data!B9-4>0,Data!B9-4,0)+L7 -> 0 | M8: =IF(Data!C9-4>0,Data!C9-4,0)+M7 -> 0 | N8: =IF(Data!D9-4>0,Data!D9-4,0)+N7 -> 0 | O8: =IF(Data!E9-4>0,Data!E9-4,0)+O7 -> 0 | P8: =IF(Data!F9-4>0,Data!F9-4,0)+P7 -> 0 | Q8: =IF(Data!G9-4>0,Data!G9-4,0)+Q7 -> 0 | R8: =IF(Data!H9-4>0,Data!H9-4,0)+R7 -> 0 | S8: =IF(Data!I9-4>0,Data!I9-4,0)+S7 -> 0 | T8: =IF(Data!B9>0,Data!B9,0)+T7 -> 0 | U8: =IF(Data!C9>0,Data!C9,0)+U7 -> 0 | V8: =IF(Data!D9>0,Data!D9,0)+V7 -> 0 | W8: =IF(Data!E9>0,Data!E9,0)+W7 -> 0 | X8: =IF(Data!F9>0,Data!F9,0)+X7 -> 0 | Y8: =IF(Data!G9>0,Data!G9,0)+Y7 -> 0 | Z8: =IF(Data!H9>0,Data!H9,0)+Z7 -> 0 | AA8: =IF(Data!I9>0,Data!I9,0)+AA7 -> 0
J9: 46029 | K9: 143 | L9: =IF(Data!B10-4>0,Data!B10-4,0)+L8 -> 0 | M9: =IF(Data!C10-4>0,Data!C10-4,0)+M8 -> 0 | N9: =IF(Data!D10-4>0,Data!D10-4,0)+N8 -> 0 | O9: =IF(Data!E10-4>0,Data!E10-4,0)+O8 -> 0 | P9: =IF(Data!F10-4>0,Data!F10-4,0)+P8 -> 0 | Q9: =IF(Data!G10-4>0,Data!G10-4,0)+Q8 -> 0 | R9: =IF(Data!H10-4>0,Data!H10-4,0)+R8 -> 0 | S9: =IF(Data!I10-4>0,Data!I10-4,0)+S8 -> 0 | T9: =IF(Data!B10>0,Data!B10,0)+T8 -> 0 | U9: =IF(Data!C10>0,Data!C10,0)+U8 -> 0 | V9: =IF(Data!D10>0,Data!D10,0)+V8 -> 0 | W9: =IF(Data!E10>0,Data!E10,0)+W8 -> 0 | X9: =IF(Data!F10>0,Data!F10,0)+X8 -> 0 | Y9: =IF(Data!G10>0,Data!G10,0)+Y8 -> 0 | Z9: =IF(Data!H10>0,Data!H10,0)+Z8 -> 0 | AA9: =IF(Data!I10>0,Data!I10,0)+AA8 -> 0
J10: 46030 | K10: 143 | L10: =IF(Data!B11-4>0,Data!B11-4,0)+L9 -> 0 | M10: =IF(Data!C11-4>0,Data!C11-4,0)+M9 -> 0 | N10: =IF(Data!D11-4>0,Data!D11-4,0)+N9 -> 0 | O10: =IF(Data!E11-4>0,Data!E11-4,0)+O9 -> 0 | P10: =IF(Data!F11-4>0,Data!F11-4,0)+P9 -> 0 | Q10: =IF(Data!G11-4>0,Data!G11-4,0)+Q9 -> 0 | R10: =IF(Data!H11-4>0,Data!H11-4,0)+R9 -> 0 | S10: =IF(Data!I11-4>0,Data!I11-4,0)+S9 -> 0 | T10: =IF(Data!B11>0,Data!B11,0)+T9 -> 0 | U10: =IF(Data!C11>0,Data!C11,0)+U9 -> 0 | V10: =IF(Data!D11>0,Data!D11,0)+V9 -> 0 | W10: =IF(Data!E11>0,Data!E11,0)+W9 -> 0 | X10: =IF(Data!F11>0,Data!F11,0)+X9 -> 0 | Y10: =IF(Data!G11>0,Data!G11,0)+Y9 -> 0 | Z10: =IF(Data!H11>0,Data!H11,0)+Z9 -> 0 | AA10: =IF(Data!I11>0,Data!I11,0)+AA9 -> 0
J11: 46031 | K11: 143 | L11: =IF(Data!B12-4>0,Data!B12-4,0)+L10 -> 0 | M11: =IF(Data!C12-4>0,Data!C12-4,0)+M10 -> 0 | N11: =IF(Data!D12-4>0,Data!D12-4,0)+N10 -> 0 | O11: =IF(Data!E12-4>0,Data!E12-4,0)+O10 -> 0 | P11: =IF(Data!F12-4>0,Data!F12-4,0)+P10 -> 0 | Q11: =IF(Data!G12-4>0,Data!G12-4,0)+Q10 -> 0 | R11: =IF(Data!H12-4>0,Data!H12-4,0)+R10 -> 0 | S11: =IF(Data!I12-4>0,Data!I12-4,0)+S10 -> 0 | T11: =IF(Data!B12>0,Data!B12,0)+T10 -> 0 | U11: =IF(Data!C12>0,Data!C12,0)+U10 -> 0 | V11: =IF(Data!D12>0,Data!D12,0)+V10 -> 0 | W11: =IF(Data!E12>0,Data!E12,0)+W10 -> 0 | X11: =IF(Data!F12>0,Data!F12,0)+X10 -> 0 | Y11: =IF(Data!G12>0,Data!G12,0)+Y10 -> 0 | Z11: =IF(Data!H12>0,Data!H12,0)+Z10 -> 0 | AA11: =IF(Data!I12>0,Data!I12,0)+AA10 -> 0
J12: 46032 | K12: 143 | L12: =IF(Data!B13-4>0,Data!B13-4,0)+L11 -> 0 | M12: =IF(Data!C13-4>0,Data!C13-4,0)+M11 -> 0 | N12: =IF(Data!D13-4>0,Data!D13-4,0)+N11 -> 0 | O12: =IF(Data!E13-4>0,Data!E13-4,0)+O11 -> 0 | P12: =IF(Data!F13-4>0,Data!F13-4,0)+P11 -> 0 | Q12: =IF(Data!G13-4>0,Data!G13-4,0)+Q11 -> 0 | R12: =IF(Data!H13-4>0,Data!H13-4,0)+R11 -> 0 | S12: =IF(Data!I13-4>0,Data!I13-4,0)+S11 -> 0 | T12: =IF(Data!B13>0,Data!B13,0)+T11 -> 0 | U12: =IF(Data!C13>0,Data!C13,0)+U11 -> 0 | V12: =IF(Data!D13>0,Data!D13,0)+V11 -> 0 | W12: =IF(Data!E13>0,Data!E13,0)+W11 -> 0 | X12: =IF(Data!F13>0,Data!F13,0)+X11 -> 0 | Y12: =IF(Data!G13>0,Data!G13,0)+Y11 -> 0 | Z12: =IF(Data!H13>0,Data!H13,0)+Z11 -> 0 | AA12: =IF(Data!I13>0,Data!I13,0)+AA11 -> 0
J13: 46033 | K13: 143 | L13: =IF(Data!B14-4>0,Data!B14-4,0)+L12 -> 0 | M13: =IF(Data!C14-4>0,Data!C14-4,0)+M12 -> 0 | N13: =IF(Data!D14-4>0,Data!D14-4,0)+N12 -> 0 | O13: =IF(Data!E14-4>0,Data!E14-4,0)+O12 -> 0 | P13: =IF(Data!F14-4>0,Data!F14-4,0)+P12 -> 0 | Q13: =IF(Data!G14-4>0,Data!G14-4,0)+Q12 -> 0 | R13: =IF(Data!H14-4>0,Data!H14-4,0)+R12 -> 0 | S13: =IF(Data!I14-4>0,Data!I14-4,0)+S12 -> 0 | T13: =IF(Data!B14>0,Data!B14,0)+T12 -> 0 | U13: =IF(Data!C14>0,Data!C14,0)+U12 -> 0 | V13: =IF(Data!D14>0,Data!D14,0)+V12 -> 0 | W13: =IF(Data!E14>0,Data!E14,0)+W12 -> 0 | X13: =IF(Data!F14>0,Data!F14,0)+X12 -> 0 | Y13: =IF(Data!G14>0,Data!G14,0)+Y12 -> 0 | Z13: =IF(Data!H14>0,Data!H14,0)+Z12 -> 0 | AA13: =IF(Data!I14>0,Data!I14,0)+AA12 -> 0
J14: 46034 | K14: 143 | L14: =IF(Data!B15-4>0,Data!B15-4,0)+L13 -> 0 | M14: =IF(Data!C15-4>0,Data!C15-4,0)+M13 -> 0 | N14: =IF(Data!D15-4>0,Data!D15-4,0)+N13 -> 0 | O14: =IF(Data!E15-4>0,Data!E15-4,0)+O13 -> 0 | P14: =IF(Data!F15-4>0,Data!F15-4,0)+P13 -> 0 | Q14: =IF(Data!G15-4>0,Data!G15-4,0)+Q13 -> 0 | R14: =IF(Data!H15-4>0,Data!H15-4,0)+R13 -> 0 | S14: =IF(Data!I15-4>0,Data!I15-4,0)+S13 -> 0 | T14: =IF(Data!B15>0,Data!B15,0)+T13 -> 0 | U14: =IF(Data!C15>0,Data!C15,0)+U13 -> 0 | V14: =IF(Data!D15>0,Data!D15,0)+V13 -> 0 | W14: =IF(Data!E15>0,Data!E15,0)+W13 -> 0 | X14: =IF(Data!F15>0,Data!F15,0)+X13 -> 0 | Y14: =IF(Data!G15>0,Data!G15,0)+Y13 -> 0 | Z14: =IF(Data!H15>0,Data!H15,0)+Z13 -> 0 | AA14: =IF(Data!I15>0,Data!I15,0)+AA13 -> 0
J15: 46035 | K15: 143 | L15: =IF(Data!B16-4>0,Data!B16-4,0)+L14 -> 0 | M15: =IF(Data!C16-4>0,Data!C16-4,0)+M14 -> 0 | N15: =IF(Data!D16-4>0,Data!D16-4,0)+N14 -> 0 | O15: =IF(Data!E16-4>0,Data!E16-4,0)+O14 -> 0 | P15: =IF(Data!F16-4>0,Data!F16-4,0)+P14 -> 0 | Q15: =IF(Data!G16-4>0,Data!G16-4,0)+Q14 -> 0 | R15: =IF(Data!H16-4>0,Data!H16-4,0)+R14 -> 0 | S15: =IF(Data!I16-4>0,Data!I16-4,0)+S14 -> 0 | T15: =IF(Data!B16>0,Data!B16,0)+T14 -> 0 | U15: =IF(Data!C16>0,Data!C16,0)+U14 -> 0 | V15: =IF(Data!D16>0,Data!D16,0)+V14 -> 0 | W15: =IF(Data!E16>0,Data!E16,0)+W14 -> 0 | X15: =IF(Data!F16>0,Data!F16,0)+X14 -> 0 | Y15: =IF(Data!G16>0,Data!G16,0)+Y14 -> 0 | Z15: =IF(Data!H16>0,Data!H16,0)+Z14 -> 0 | AA15: =IF(Data!I16>0,Data!I16,0)+AA14 -> 0
... J23: 46043 | K23: 143 | L23: =IF(Data!B24-4>0,Data!B24-4,0)+L22 -> 0 | M23: =IF(Data!C24-4>0,Data!C24-4,0)+M22 -> 0 | N23: =IF(Data!D24-4>0,Data!D24-4,0)+N22 -> 0 | O23: =IF(Data!E24-4>0,Data!E24-4,0)+O22 -> 0 | P23: =IF(Data!F24-4>0,Data!F24-4,0)+P22 -> 0 | Q23: =IF(Data!G24-4>0,Data!G24-4,0)+Q22 -> 0 | R23: =IF(Data!H24-4>0,Data!H24-4,0)+R22 -> 0 | S23: =IF(Data!I24-4>0,Data!I24-4,0)+S22 -> 0 | T23: =IF(Data!B24>0,Data!B24,0)+T22 -> 0 | U23: =IF(Data!C24>0,Data!C24,0)+U22 -> 0 | V23: =IF(Data!D24>0,Data!D24,0)+V22 -> 0 | W23: =IF(Data!E24>0,Data!E24,0)+W22 -> 0 | X23: =IF(Data!F24>0,Data!F24,0)+X22 -> 0 | Y23: =IF(Data!G24>0,Data!G24,0)+Y22 -> 0 | Z23: =IF(Data!H24>0,Data!H24,0)+Z22 -> 0 | AA23: =IF(Data!I24>0,Data!I24,0)+AA22 -> 0
A24: Base 4°C | B24: =M2 -> #NAME? | C24: =N2 -> #NAME? | D24: =O2 -> #NAME? | E24: =P2 -> #NAME? | F24: =Q2 -> #NAME? | G24: =R2 -> #NAME? | H24: =S2 -> #NAME? | J24: 46044 | K24: 143 | L24: =IF(Data!B25-4>0,Data!B25-4,0)+L23 -> 0 | M24: =IF(Data!C25-4>0,Data!C25-4,0)+M23 -> 0 | N24: =IF(Data!D25-4>0,Data!D25-4,0)+N23 -> 0 | O24: =IF(Data!E25-4>0,Data!E25-4,0)+O23 -> 0 | P24: =IF(Data!F25-4>0,Data!F25-4,0)+P23 -> 0 | Q24: =IF(Data!G25-4>0,Data!G25-4,0)+Q23 -> 0 | R24: =IF(Data!H25-4>0,Data!H25-4,0)+R23 -> 0 | S24: =IF(Data!I25-4>0,Data!I25-4,0)+S23 -> 0 | T24: =IF(Data!B25>0,Data!B25,0)+T23 -> 0 | U24: =IF(Data!C25>0,Data!C25,0)+U23 -> 0 | V24: =IF(Data!D25>0,Data!D25,0)+V23 -> 0 | W24: =IF(Data!E25>0,Data!E25,0)+W23 -> 0 | X24: =IF(Data!F25>0,Data!F25,0)+X23 -> 0 | Y24: =IF(Data!G25>0,Data!G25,0)+Y23 -> 0 | Z24: =IF(Data!H25>0,Data!H25,0)+Z23 -> 0 | AA24: =IF(Data!I25>0,Data!I25,0)+AA23 -> 0
A25: Cumul de Température (°C) | B25: =M92 -> 0 | C25: =N92 -> 0 | D25: =O92 -> 0 | E25: =P92 -> 0 | F25: =Q92 -> 0 | G25: =R92 -> 0 | H25: =S92 -> 0 | J25: 46045 | K25: 143 | L25: =IF(Data!B26-4>0,Data!B26-4,0)+L24 -> 0 | M25: =IF(Data!C26-4>0,Data!C26-4,0)+M24 -> 0 | N25: =IF(Data!D26-4>0,Data!D26-4,0)+N24 -> 0 | O25: =IF(Data!E26-4>0,Data!E26-4,0)+O24 -> 0 | P25: =IF(Data!F26-4>0,Data!F26-4,0)+P24 -> 0 | Q25: =IF(Data!G26-4>0,Data!G26-4,0)+Q24 -> 0 | R25: =IF(Data!H26-4>0,Data!H26-4,0)+R24 -> 0 | S25: =IF(Data!I26-4>0,Data!I26-4,0)+S24 -> 0 | T25: =IF(Data!B26>0,Data!B26,0)+T24 -> 0 | U25: =IF(Data!C26>0,Data!C26,0)+U24 -> 0 | V25: =IF(Data!D26>0,Data!D26,0)+V24 -> 0 | W25: =IF(Data!E26>0,Data!E26,0)+W24 -> 0 | X25: =IF(Data!F26>0,Data!F26,0)+X24 -> 0 | Y25: =IF(Data!G26>0,Data!G26,0)+Y24 -> 0 | Z25: =IF(Data!H26>0,Data!H26,0)+Z24 -> 0 | AA25: =IF(Data!I26>0,Data!I26,0)+AA24 -> 0
J26: 46046 | K26: 143 | L26: =IF(Data!B27-4>0,Data!B27-4,0)+L25 -> 0 | M26: =IF(Data!C27-4>0,Data!C27-4,0)+M25 -> 0 | N26: =IF(Data!D27-4>0,Data!D27-4,0)+N25 -> 0 | O26: =IF(Data!E27-4>0,Data!E27-4,0)+O25 -> 0 | P26: =IF(Data!F27-4>0,Data!F27-4,0)+P25 -> 0 | Q26: =IF(Data!G27-4>0,Data!G27-4,0)+Q25 -> 0 | R26: =IF(Data!H27-4>0,Data!H27-4,0)+R25 -> 0 | S26: =IF(Data!I27-4>0,Data!I27-4,0)+S25 -> 0 | T26: =IF(Data!B27>0,Data!B27,0)+T25 -> 0 | U26: =IF(Data!C27>0,Data!C27,0)+U25 -> 0 | V26: =IF(Data!D27>0,Data!D27,0)+V25 -> 0 | W26: =IF(Data!E27>0,Data!E27,0)+W25 -> 0 | X26: =IF(Data!F27>0,Data!F27,0)+X25 -> 0 | Y26: =IF(Data!G27>0,Data!G27,0)+Y25 -> 0 | Z26: =IF(Data!H27>0,Data!H27,0)+Z25 -> 0 | AA26: =IF(Data!I27>0,Data!I27,0)+AA25 -> 0
A27: Base 0°C | B27: =U2 -> #NAME? | C27: =V2 -> #NAME? | D27: =W2 -> #NAME? | E27: =X2 -> #NAME? | F27: =Y2 -> #NAME? | G27: =Z2 -> #NAME? | H27: =AA2 -> #NAME? | J27: 46047 | K27: 143 | L27: =IF(Data!B28-4>0,Data!B28-4,0)+L26 -> 0 | M27: =IF(Data!C28-4>0,Data!C28-4,0)+M26 -> 0 | N27: =IF(Data!D28-4>0,Data!D28-4,0)+N26 -> 0 | O27: =IF(Data!E28-4>0,Data!E28-4,0)+O26 -> 0 | P27: =IF(Data!F28-4>0,Data!F28-4,0)+P26 -> 0 | Q27: =IF(Data!G28-4>0,Data!G28-4,0)+Q26 -> 0 | R27: =IF(Data!H28-4>0,Data!H28-4,0)+R26 -> 0 | S27: =IF(Data!I28-4>0,Data!I28-4,0)+S26 -> 0 | T27: =IF(Data!B28>0,Data!B28,0)+T26 -> 0 | U27: =IF(Data!C28>0,Data!C28,0)+U26 -> 0 | V27: =IF(Data!D28>0,Data!D28,0)+V26 -> 0 | W27: =IF(Data!E28>0,Data!E28,0)+W26 -> 0 | X27: =IF(Data!F28>0,Data!F28,0)+X26 -> 0 | Y27: =IF(Data!G28>0,Data!G28,0)+Y26 -> 0 | Z27: =IF(Data!H28>0,Data!H28,0)+Z26 -> 0 | AA27: =IF(Data!I28>0,Data!I28,0)+AA26 -> 0
A28: Cumul de Température (°C) | B28: =U92 -> 0 | C28: =V92 -> 0 | D28: =W92 -> 0 | E28: =X92 -> 0 | F28: =Y92 -> 0 | G28: =Z92 -> 0 | H28: =AA92 -> 0 | J28: 46048 | K28: 143 | L28: =IF(Data!B29-4>0,Data!B29-4,0)+L27 -> 0 | M28: =IF(Data!C29-4>0,Data!C29-4,0)+M27 -> 0 | N28: =IF(Data!D29-4>0,Data!D29-4,0)+N27 -> 0 | O28: =IF(Data!E29-4>0,Data!E29-4,0)+O27 -> 0 | P28: =IF(Data!F29-4>0,Data!F29-4,0)+P27 -> 0 | Q28: =IF(Data!G29-4>0,Data!G29-4,0)+Q27 -> 0 | R28: =IF(Data!H29-4>0,Data!H29-4,0)+R27 -> 0 | S28: =IF(Data!I29-4>0,Data!I29-4,0)+S27 -> 0 | T28: =IF(Data!B29>0,Data!B29,0)+T27 -> 0 | U28: =IF(Data!C29>0,Data!C29,0)+U27 -> 0 | V28: =IF(Data!D29>0,Data!D29,0)+V27 -> 0 | W28: =IF(Data!E29>0,Data!E29,0)+W27 -> 0 | X28: =IF(Data!F29>0,Data!F29,0)+X27 -> 0 | Y28: =IF(Data!G29>0,Data!G29,0)+Y27 -> 0 | Z28: =IF(Data!H29>0,Data!H29,0)+Z27 -> 0 | AA28: =IF(Data!I29>0,Data!I29,0)+AA27 -> 0
J29: 46049 | K29: 143 | L29: =IF(Data!B30-4>0,Data!B30-4,0)+L28 -> 0 | M29: =IF(Data!C30-4>0,Data!C30-4,0)+M28 -> 0 | N29: =IF(Data!D30-4>0,Data!D30-4,0)+N28 -> 0 | O29: =IF(Data!E30-4>0,Data!E30-4,0)+O28 -> 0 | P29: =IF(Data!F30-4>0,Data!F30-4,0)+P28 -> 0 | Q29: =IF(Data!G30-4>0,Data!G30-4,0)+Q28 -> 0 | R29: =IF(Data!H30-4>0,Data!H30-4,0)+R28 -> 0 | S29: =IF(Data!I30-4>0,Data!I30-4,0)+S28 -> 0 | T29: =IF(Data!B30>0,Data!B30,0)+T28 -> 0 | U29: =IF(Data!C30>0,Data!C30,0)+U28 -> 0 | V29: =IF(Data!D30>0,Data!D30,0)+V28 -> 0 | W29: =IF(Data!E30>0,Data!E30,0)+W28 -> 0 | X29: =IF(Data!F30>0,Data!F30,0)+X28 -> 0 | Y29: =IF(Data!G30>0,Data!G30,0)+Y28 -> 0 | Z29: =IF(Data!H30>0,Data!H30,0)+Z28 -> 0 | AA29: =IF(Data!I30>0,Data!I30,0)+AA28 -> 0
J30: 46050 | K30: 143 | L30: =IF(Data!B31-4>0,Data!B31-4,0)+L29 -> 0 | M30: =IF(Data!C31-4>0,Data!C31-4,0)+M29 -> 0 | N30: =IF(Data!D31-4>0,Data!D31-4,0)+N29 -> 0 | O30: =IF(Data!E31-4>0,Data!E31-4,0)+O29 -> 0 | P30: =IF(Data!F31-4>0,Data!F31-4,0)+P29 -> 0 | Q30: =IF(Data!G31-4>0,Data!G31-4,0)+Q29 -> 0 | R30: =IF(Data!H31-4>0,Data!H31-4,0)+R29 -> 0 | S30: =IF(Data!I31-4>0,Data!I31-4,0)+S29 -> 0 | T30: =IF(Data!B31>0,Data!B31,0)+T29 -> 0 | U30: =IF(Data!C31>0,Data!C31,0)+U29 -> 0 | V30: =IF(Data!D31>0,Data!D31,0)+V29 -> 0 | W30: =IF(Data!E31>0,Data!E31,0)+W29 -> 0 | X30: =IF(Data!F31>0,Data!F31,0)+X29 -> 0 | Y30: =IF(Data!G31>0,Data!G31,0)+Y29 -> 0 | Z30: =IF(Data!H31>0,Data!H31,0)+Z29 -> 0 | AA30: =IF(Data!I31>0,Data!I31,0)+AA29 -> 0
J31: 46051 | K31: 143 | L31: =IF(Data!B32-4>0,Data!B32-4,0)+L30 -> 0 | M31: =IF(Data!C32-4>0,Data!C32-4,0)+M30 -> 0 | N31: =IF(Data!D32-4>0,Data!D32-4,0)+N30 -> 0 | O31: =IF(Data!E32-4>0,Data!E32-4,0)+O30 -> 0 | P31: =IF(Data!F32-4>0,Data!F32-4,0)+P30 -> 0 | Q31: =IF(Data!G32-4>0,Data!G32-4,0)+Q30 -> 0 | R31: =IF(Data!H32-4>0,Data!H32-4,0)+R30 -> 0 | S31: =IF(Data!I32-4>0,Data!I32-4,0)+S30 -> 0 | T31: =IF(Data!B32>0,Data!B32,0)+T30 -> 0 | U31: =IF(Data!C32>0,Data!C32,0)+U30 -> 0 | V31: =IF(Data!D32>0,Data!D32,0)+V30 -> 0 | W31: =IF(Data!E32>0,Data!E32,0)+W30 -> 0 | X31: =IF(Data!F32>0,Data!F32,0)+X30 -> 0 | Y31: =IF(Data!G32>0,Data!G32,0)+Y30 -> 0 | Z31: =IF(Data!H32>0,Data!H32,0)+Z30 -> 0 | AA31: =IF(Data!I32>0,Data!I32,0)+AA30 -> 0
J32: 46052 | K32: 143 | L32: =IF(Data!B33-4>0,Data!B33-4,0)+L31 -> 0 | M32: =IF(Data!C33-4>0,Data!C33-4,0)+M31 -> 0 | N32: =IF(Data!D33-4>0,Data!D33-4,0)+N31 -> 0 | O32: =IF(Data!E33-4>0,Data!E33-4,0)+O31 -> 0 | P32: =IF(Data!F33-4>0,Data!F33-4,0)+P31 -> 0 | Q32: =IF(Data!G33-4>0,Data!G33-4,0)+Q31 -> 0 | R32: =IF(Data!H33-4>0,Data!H33-4,0)+R31 -> 0 | S32: =IF(Data!I33-4>0,Data!I33-4,0)+S31 -> 0 | T32: =IF(Data!B33>0,Data!B33,0)+T31 -> 0 | U32: =IF(Data!C33>0,Data!C33,0)+U31 -> 0 | V32: =IF(Data!D33>0,Data!D33,0)+V31 -> 0 | W32: =IF(Data!E33>0,Data!E33,0)+W31 -> 0 | X32: =IF(Data!F33>0,Data!F33,0)+X31 -> 0 | Y32: =IF(Data!G33>0,Data!G33,0)+Y31 -> 0 | Z32: =IF(Data!H33>0,Data!H33,0)+Z31 -> 0 | AA32: =IF(Data!I33>0,Data!I33,0)+AA31 -> 0
J33: 46053 | K33: 143 | L33: =IF(Data!B34-4>0,Data!B34-4,0)+L32 -> 0 | M33: =IF(Data!C34-4>0,Data!C34-4,0)+M32 -> 0 | N33: =IF(Data!D34-4>0,Data!D34-4,0)+N32 -> 0 | O33: =IF(Data!E34-4>0,Data!E34-4,0)+O32 -> 0 | P33: =IF(Data!F34-4>0,Data!F34-4,0)+P32 -> 0 | Q33: =IF(Data!G34-4>0,Data!G34-4,0)+Q32 -> 0 | R33: =IF(Data!H34-4>0,Data!H34-4,0)+R32 -> 0 | S33: =IF(Data!I34-4>0,Data!I34-4,0)+S32 -> 0 | T33: =IF(Data!B34>0,Data!B34,0)+T32 -> 0 | U33: =IF(Data!C34>0,Data!C34,0)+U32 -> 0 | V33: =IF(Data!D34>0,Data!D34,0)+V32 -> 0 | W33: =IF(Data!E34>0,Data!E34,0)+W32 -> 0 | X33: =IF(Data!F34>0,Data!F34,0)+X32 -> 0 | Y33: =IF(Data!G34>0,Data!G34,0)+Y32 -> 0 | Z33: =IF(Data!H34>0,Data!H34,0)+Z32 -> 0 | AA33: =IF(Data!I34>0,Data!I34,0)+AA32 -> 0
J34: 46054 | K34: 143 | L34: =IF(Data!B35-4>0,Data!B35-4,0)+L33 -> 0 | M34: =IF(Data!C35-4>0,Data!C35-4,0)+M33 -> 0 | N34: =IF(Data!D35-4>0,Data!D35-4,0)+N33 -> 0 | O34: =IF(Data!E35-4>0,Data!E35-4,0)+O33 -> 0 | P34: =IF(Data!F35-4>0,Data!F35-4,0)+P33 -> 0 | Q34: =IF(Data!G35-4>0,Data!G35-4,0)+Q33 -> 0 | R34: =IF(Data!H35-4>0,Data!H35-4,0)+R33 -> 0 | S34: =IF(Data!I35-4>0,Data!I35-4,0)+S33 -> 0 | T34: =IF(Data!B35>0,Data!B35,0)+T33 -> 0 | U34: =IF(Data!C35>0,Data!C35,0)+U33 -> 0 | V34: =IF(Data!D35>0,Data!D35,0)+V33 -> 0 | W34: =IF(Data!E35>0,Data!E35,0)+W33 -> 0 | X34: =IF(Data!F35>0,Data!F35,0)+X33 -> 0 | Y34: =IF(Data!G35>0,Data!G35,0)+Y33 -> 0 | Z34: =IF(Data!H35>0,Data!H35,0)+Z33 -> 0 | AA34: =IF(Data!I35>0,Data!I35,0)+AA33 -> 0
J35: 46055 | K35: 143 | L35: =IF(Data!B36-4>0,Data!B36-4,0)+L34 -> 0 | M35: =IF(Data!C36-4>0,Data!C36-4,0)+M34 -> 0 | N35: =IF(Data!D36-4>0,Data!D36-4,0)+N34 -> 0 | O35: =IF(Data!E36-4>0,Data!E36-4,0)+O34 -> 0 | P35: =IF(Data!F36-4>0,Data!F36-4,0)+P34 -> 0 | Q35: =IF(Data!G36-4>0,Data!G36-4,0)+Q34 -> 0 | R35: =IF(Data!H36-4>0,Data!H36-4,0)+R34 -> 0 | S35: =IF(Data!I36-4>0,Data!I36-4,0)+S34 -> 0 | T35: =IF(Data!B36>0,Data!B36,0)+T34 -> 0 | U35: =IF(Data!C36>0,Data!C36,0)+U34 -> 0 | V35: =IF(Data!D36>0,Data!D36,0)+V34 -> 0 | W35: =IF(Data!E36>0,Data!E36,0)+W34 -> 0 | X35: =IF(Data!F36>0,Data!F36,0)+X34 -> 0 | Y35: =IF(Data!G36>0,Data!G36,0)+Y34 -> 0 | Z35: =IF(Data!H36>0,Data!H36,0)+Z34 -> 0 | AA35: =IF(Data!I36>0,Data!I36,0)+AA34 -> 0
J36: 46056 | K36: 143 | L36: =IF(Data!B37-4>0,Data!B37-4,0)+L35 -> 0 | M36: =IF(Data!C37-4>0,Data!C37-4,0)+M35 -> 0 | N36: =IF(Data!D37-4>0,Data!D37-4,0)+N35 -> 0 | O36: =IF(Data!E37-4>0,Data!E37-4,0)+O35 -> 0 | P36: =IF(Data!F37-4>0,Data!F37-4,0)+P35 -> 0 | Q36: =IF(Data!G37-4>0,Data!G37-4,0)+Q35 -> 0 | R36: =IF(Data!H37-4>0,Data!H37-4,0)+R35 -> 0 | S36: =IF(Data!I37-4>0,Data!I37-4,0)+S35 -> 0 | T36: =IF(Data!B37>0,Data!B37,0)+T35 -> 0 | U36: =IF(Data!C37>0,Data!C37,0)+U35 -> 0 | V36: =IF(Data!D37>0,Data!D37,0)+V35 -> 0 | W36: =IF(Data!E37>0,Data!E37,0)+W35 -> 0 | X36: =IF(Data!F37>0,Data!F37,0)+X35 -> 0 | Y36: =IF(Data!G37>0,Data!G37,0)+Y35 -> 0 | Z36: =IF(Data!H37>0,Data!H37,0)+Z35 -> 0 | AA36: =IF(Data!I37>0,Data!I37,0)+AA35 -> 0
J37: 46057 | K37: 143 | L37: =IF(Data!B38-4>0,Data!B38-4,0)+L36 -> 0 | M37: =IF(Data!C38-4>0,Data!C38-4,0)+M36 -> 0 | N37: =IF(Data!D38-4>0,Data!D38-4,0)+N36 -> 0 | O37: =IF(Data!E38-4>0,Data!E38-4,0)+O36 -> 0 | P37: =IF(Data!F38-4>0,Data!F38-4,0)+P36 -> 0 | Q37: =IF(Data!G38-4>0,Data!G38-4,0)+Q36 -> 0 | R37: =IF(Data!H38-4>0,Data!H38-4,0)+R36 -> 0 | S37: =IF(Data!I38-4>0,Data!I38-4,0)+S36 -> 0 | T37: =IF(Data!B38>0,Data!B38,0)+T36 -> 0 | U37: =IF(Data!C38>0,Data!C38,0)+U36 -> 0 | V37: =IF(Data!D38>0,Data!D38,0)+V36 -> 0 | W37: =IF(Data!E38>0,Data!E38,0)+W36 -> 0 | X37: =IF(Data!F38>0,Data!F38,0)+X36 -> 0 | Y37: =IF(Data!G38>0,Data!G38,0)+Y36 -> 0 | Z37: =IF(Data!H38>0,Data!H38,0)+Z36 -> 0 | AA37: =IF(Data!I38>0,Data!I38,0)+AA36 -> 0
J38: 46058 | K38: 143 | L38: =IF(Data!B39-4>0,Data!B39-4,0)+L37 -> 0 | M38: =IF(Data!C39-4>0,Data!C39-4,0)+M37 -> 0 | N38: =IF(Data!D39-4>0,Data!D39-4,0)+N37 -> 0 | O38: =IF(Data!E39-4>0,Data!E39-4,0)+O37 -> 0 | P38: =IF(Data!F39-4>0,Data!F39-4,0)+P37 -> 0 | Q38: =IF(Data!G39-4>0,Data!G39-4,0)+Q37 -> 0 | R38: =IF(Data!H39-4>0,Data!H39-4,0)+R37 -> 0 | S38: =IF(Data!I39-4>0,Data!I39-4,0)+S37 -> 0 | T38: =IF(Data!B39>0,Data!B39,0)+T37 -> 0 | U38: =IF(Data!C39>0,Data!C39,0)+U37 -> 0 | V38: =IF(Data!D39>0,Data!D39,0)+V37 -> 0 | W38: =IF(Data!E39>0,Data!E39,0)+W37 -> 0 | X38: =IF(Data!F39>0,Data!F39,0)+X37 -> 0 | Y38: =IF(Data!G39>0,Data!G39,0)+Y37 -> 0 | Z38: =IF(Data!H39>0,Data!H39,0)+Z37 -> 0 | AA38: =IF(Data!I39>0,Data!I39,0)+AA37 -> 0
J39: 46059 | K39: 143 | L39: =IF(Data!B40-4>0,Data!B40-4,0)+L38 -> 0 | M39: =IF(Data!C40-4>0,Data!C40-4,0)+M38 -> 0 | N39: =IF(Data!D40-4>0,Data!D40-4,0)+N38 -> 0 | O39: =IF(Data!E40-4>0,Data!E40-4,0)+O38 -> 0 | P39: =IF(Data!F40-4>0,Data!F40-4,0)+P38 -> 0 | Q39: =IF(Data!G40-4>0,Data!G40-4,0)+Q38 -> 0 | R39: =IF(Data!H40-4>0,Data!H40-4,0)+R38 -> 0 | S39: =IF(Data!I40-4>0,Data!I40-4,0)+S38 -> 0 | T39: =IF(Data!B40>0,Data!B40,0)+T38 -> 0 | U39: =IF(Data!C40>0,Data!C40,0)+U38 -> 0 | V39: =IF(Data!D40>0,Data!D40,0)+V38 -> 0 | W39: =IF(Data!E40>0,Data!E40,0)+W38 -> 0 | X39: =IF(Data!F40>0,Data!F40,0)+X38 -> 0 | Y39: =IF(Data!G40>0,Data!G40,0)+Y38 -> 0 | Z39: =IF(Data!H40>0,Data!H40,0)+Z38 -> 0 | AA39: =IF(Data!I40>0,Data!I40,0)+AA38 -> 0
J40: 46060 | K40: 143 | L40: =IF(Data!B41-4>0,Data!B41-4,0)+L39 -> 0 | M40: =IF(Data!C41-4>0,Data!C41-4,0)+M39 -> 0 | N40: =IF(Data!D41-4>0,Data!D41-4,0)+N39 -> 0 | O40: =IF(Data!E41-4>0,Data!E41-4,0)+O39 -> 0 | P40: =IF(Data!F41-4>0,Data!F41-4,0)+P39 -> 0 | Q40: =IF(Data!G41-4>0,Data!G41-4,0)+Q39 -> 0 | R40: =IF(Data!H41-4>0,Data!H41-4,0)+R39 -> 0 | S40: =IF(Data!I41-4>0,Data!I41-4,0)+S39 -> 0 | T40: =IF(Data!B41>0,Data!B41,0)+T39 -> 0 | U40: =IF(Data!C41>0,Data!C41,0)+U39 -> 0 | V40: =IF(Data!D41>0,Data!D41,0)+V39 -> 0 | W40: =IF(Data!E41>0,Data!E41,0)+W39 -> 0 | X40: =IF(Data!F41>0,Data!F41,0)+X39 -> 0 | Y40: =IF(Data!G41>0,Data!G41,0)+Y39 -> 0 | Z40: =IF(Data!H41>0,Data!H41,0)+Z39 -> 0 | AA40: =IF(Data!I41>0,Data!I41,0)+AA39 -> 0
... J92: 46112 | K92: 143 | L92: =IF(Data!B93-4>0,Data!B93-4,0)+L91 -> 0 | M92: =IF(Data!C93-4>0,Data!C93-4,0)+M91 -> 0 | N92: =IF(Data!D93-4>0,Data!D93-4,0)+N91 -> 0 | O92: =IF(Data!E93-4>0,Data!E93-4,0)+O91 -> 0 | P92: =IF(Data!F93-4>0,Data!F93-4,0)+P91 -> 0 | Q92: =IF(Data!G93-4>0,Data!G93-4,0)+Q91 -> 0 | R92: =IF(Data!H93-4>0,Data!H93-4,0)+R91 -> 0 | S92: =IF(Data!I93-4>0,Data!I93-4,0)+S91 -> 0 | T92: =IF(Data!B93>0,Data!B93,0)+T91 -> 0 | U92: =IF(Data!C93>0,Data!C93,0)+U91 -> 0 | V92: =IF(Data!D93>0,Data!D93,0)+V91 -> 0 | W92: =IF(Data!E93>0,Data!E93,0)+W91 -> 0 | X92: =IF(Data!F93>0,Data!F93,0)+X91 -> 0 | Y92: =IF(Data!G93>0,Data!G93,0)+Y91 -> 0 | Z92: =IF(Data!H93>0,Data!H93,0)+Z91 -> 0 | AA92: =IF(Data!I93>0,Data!I93,0)+AA91 -> 0

Sheet Est
J1: Département | L1: =Data!P3 -> 0 | M1: =Data!Q3 -> 0 | N1: =Data!R3 -> 0 | O1: =Data!S3 -> 0 | P1: =Data!T3 -> 0 | Q1: =Data!U3 -> 0 | R1: =Data!V3 -> 0 | T1: =L1 -> 0 | U1: =M1 -> 0 | V1: =N1 -> 0 | W1: =O1 -> 0 | X1: =P1 -> 0 | Y1: =Q1 -> 0 | Z1: =R1 -> 0
J2: Ville | K2: Seuil (143°J) | L2: =_xlfn.CONCAT(Data!P1," (",Data!P2,")") -> #NAME? | M2: =_xlfn.CONCAT(Data!Q1," (",Data!Q2,")") -> #NAME? | N2: =_xlfn.CONCAT(Data!R1," (",Data!R2,")") -> #NAME? | O2: =_xlfn.CONCAT(Data!S1," (",Data!S2,")") -> #NAME? | P2: =_xlfn.CONCAT(Data!T1," (",Data!T2,")") -> #NAME? | Q2: =_xlfn.CONCAT(Data!U1," (",Data!U2,")") -> #NAME? | R2: =_xlfn.CONCAT(Data!V1," (",Data!V2,")") -> #NAME? | T2: =L2 -> #NAME? | U2: =M2 -> #NAME? | V2: =N2 -> #NAME? | W2: =O2 -> #NAME? | X2: =P2 -> #NAME? | Y2: =Q2 -> #NAME? | Z2: =R2 -> #NAME?
J3: 46023 | K3: 143 | L3: =IF(Data!P4-4>0,Data!P4-4,0) -> 0 | M3: =IF(Data!Q4-4>0,Data!Q4-4,0) -> 0 | N3: =IF(Data!R4-4>0,Data!R4-4,0) -> 0 | O3: =IF(Data!S4-4>0,Data!S4-4,0) -> 0 | P3: =IF(Data!T4-4>0,Data!T4-4,0) -> 0 | Q3: =IF(Data!U4-4>0,Data!U4-4,0) -> 0 | R3: =IF(Data!V4-4>0,Data!V4-4,0) -> 0 | T3: =IF(Data!P4>0,Data!P4,0) -> 0 | U3: =IF(Data!Q4>0,Data!Q4,0) -> 0 | V3: =IF(Data!R4>0,Data!R4,0) -> 0 | W3: =IF(Data!S4>0,Data!S4,0) -> 0 | X3: =IF(Data!T4>0,Data!T4,0) -> 0 | Y3: =IF(Data!U4>0,Data!U4,0) -> 0 | Z3: =IF(Data!V4>0,Data!V4,0) -> 0
J4: 46024 | K4: 143 | L4: =IF(Data!P5-4>0,Data!P5-4,0)+L3 -> 0 | M4: =IF(Data!Q5-4>0,Data!Q5-4,0)+M3 -> 0 | N4: =IF(Data!R5-4>0,Data!R5-4,0)+N3 -> 0 | O4: =IF(Data!S5-4>0,Data!S5-4,0)+O3 -> 0 | P4: =IF(Data!T5-4>0,Data!T5-4,0)+P3 -> 0 | Q4: =IF(Data!U5-4>0,Data!U5-4,0)+Q3 -> 0 | R4: =IF(Data!V5-4>0,Data!V5-4,0)+R3 -> 0 | T4: =IF(Data!P5>0,Data!P5,0)+T3 -> 0 | U4: =IF(Data!Q5>0,Data!Q5,0)+U3 -> 0 | V4: =IF(Data!R5>0,Data!R5,0)+V3 -> 0 | W4: =IF(Data!S5>0,Data!S5,0)+W3 -> 0 | X4: =IF(Data!T5>0,Data!T5,0)+X3 -> 0 | Y4: =IF(Data!U5>0,Data!U5,0)+Y3 -> 0 | Z4: =IF(Data!V5>0,Data!V5,0)+Z3 -> 0
J5: 46025 | K5: 143 | L5: =IF(Data!P6-4>0,Data!P6-4,0)+L4 -> 0 | M5: =IF(Data!Q6-4>0,Data!Q6-4,0)+M4 -> 0 | N5: =IF(Data!R6-4>0,Data!R6-4,0)+N4 -> 0 | O5: =IF(Data!S6-4>0,Data!S6-4,0)+O4 -> 0 | P5: =IF(Data!T6-4>0,Data!T6-4,0)+P4 -> 0 | Q5: =IF(Data!U6-4>0,Data!U6-4,0)+Q4 -> 0 | R5: =IF(Data!V6-4>0,Data!V6-4,0)+R4 -> 0 | T5: =IF(Data!P6>0,Data!P6,0)+T4 -> 0 | U5: =IF(Data!Q6>0,Data!Q6,0)+U4 -> 0 | V5: =IF(Data!R6>0,Data!R6,0)+V4 -> 0 | W5: =IF(Data!S6>0,Data!S6,0)+W4 -> 0 | X5: =IF(Data!T6>0,Data!T6,0)+X4 -> 0 | Y5: =IF(Data!U6>0,Data!U6,0)+Y4 -> 0 | Z5: =IF(Data!V6>0,Data!V6,0)+Z4 -> 0
J6: 46026 | K6: 143 | L6: =IF(Data!P7-4>0,Data!P7-4,0)+L5 -> 0 | M6: =IF(Data!Q7-4>0,Data!Q7-4,0)+M5 -> 0 | N6: =IF(Data!R7-4>0,Data!R7-4,0)+N5 -> 0 | O6: =IF(Data!S7-4>0,Data!S7-4,0)+O5 -> 0 | P6: =IF(Data!T7-4>0,Data!T7-4,0)+P5 -> 0 | Q6: =IF(Data!U7-4>0,Data!U7-4,0)+Q5 -> 0 | R6: =IF(Data!V7-4>0,Data!V7-4,0)+R5 -> 0 | T6: =IF(Data!P7>0,Data!P7,0)+T5 -> 0 | U6: =IF(Data!Q7>0,Data!Q7,0)+U5 -> 0 | V6: =IF(Data!R7>0,Data!R7,0)+V5 -> 0 | W6: =IF(Data!S7>0,Data!S7,0)+W5 -> 0 | X6: =IF(Data!T7>0,Data!T7,0)+X5 -> 0 | Y6: =IF(Data!U7>0,Data!U7,0)+Y5 -> 0 | Z6: =IF(Data!V7>0,Data!V7,0)+Z5 -> 0
J7: 46027 | K7: 143 | L7: =IF(Data!P8-4>0,Data!P8-4,0)+L6 -> 0 | M7: =IF(Data!Q8-4>0,Data!Q8-4,0)+M6 -> 0 | N7: =IF(Data!R8-4>0,Data!R8-4,0)+N6 -> 0 | O7: =IF(Data!S8-4>0,Data!S8-4,0)+O6 -> 0 | P7: =IF(Data!T8-4>0,Data!T8-4,0)+P6 -> 0 | Q7: =IF(Data!U8-4>0,Data!U8-4,0)+Q6 -> 0 | R7: =IF(Data!V8-4>0,Data!V8-4,0)+R6 -> 0 | T7: =IF(Data!P8>0,Data!P8,0)+T6 -> 0 | U7: =IF(Data!Q8>0,Data!Q8,0)+U6 -> 0 | V7: =IF(Data!R8>0,Data!R8,0)+V6 -> 0 | W7: =IF(Data!S8>0,Data!S8,0)+W6 -> 0 | X7: =IF(Data!T8>0,Data!T8,0)+X6 -> 0 | Y7: =IF(Data!U8>0,Data!U8,0)+Y6 -> 0 | Z7: =IF(Data!V8>0,Data!V8,0)+Z6 -> 0
J8: 46028 | K8: 143 | L8: =IF(Data!P9-4>0,Data!P9-4,0)+L7 -> 0 | M8: =IF(Data!Q9-4>0,Data!Q9-4,0)+M7 -> 0 | N8: =IF(Data!R9-4>0,Data!R9-4,0)+N7 -> 0 | O8: =IF(Data!S9-4>0,Data!S9-4,0)+O7 -> 0 | P8: =IF(Data!T9-4>0,Data!T9-4,0)+P7 -> 0 | Q8: =IF(Data!U9-4>0,Data!U9-4,0)+Q7 -> 0 | R8: =IF(Data!V9-4>0,Data!V9-4,0)+R7 -> 0 | T8: =IF(Data!P9>0,Data!P9,0)+T7 -> 0 | U8: =IF(Data!Q9>0,Data!Q9,0)+U7 -> 0 | V8: =IF(Data!R9>0,Data!R9,0)+V7 -> 0 | W8: =IF(Data!S9>0,Data!S9,0)+W7 -> 0 | X8: =IF(Data!T9>0,Data!T9,0)+X7 -> 0 | Y8: =IF(Data!U9>0,Data!U9,0)+Y7 -> 0 | Z8: =IF(Data!V9>0,Data!V9,0)+Z7 -> 0
J9: 46029 | K9: 143 | L9: =IF(Data!P10-4>0,Data!P10-4,0)+L8 -> 0 | M9: =IF(Data!Q10-4>0,Data!Q10-4,0)+M8 -> 0 | N9: =IF(Data!R10-4>0,Data!R10-4,0)+N8 -> 0 | O9: =IF(Data!S10-4>0,Data!S10-4,0)+O8 -> 0 | P9: =IF(Data!T10-4>0,Data!T10-4,0)+P8 -> 0 | Q9: =IF(Data!U10-4>0,Data!U10-4,0)+Q8 -> 0 | R9: =IF(Data!V10-4>0,Data!V10-4,0)+R8 -> 0 | T9: =IF(Data!P10>0,Data!P10,0)+T8 -> 0 | U9: =IF(Data!Q10>0,Data!Q10,0)+U8 -> 0 | V9: =IF(Data!R10>0,Data!R10,0)+V8 -> 0 | W9: =IF(Data!S10>0,Data!S10,0)+W8 -> 0 | X9: =IF(Data!T10>0,Data!T10,0)+X8 -> 0 | Y9: =IF(Data!U10>0,Data!U10,0)+Y8 -> 0 | Z9: =IF(Data!V10>0,Data!V10,0)+Z8 -> 0
J10: 46030 | K10: 143 | L10: =IF(Data!P11-4>0,Data!P11-4,0)+L9 -> 0 | M10: =IF(Data!Q11-4>0,Data!Q11-4,0)+M9 -> 0 | N10: =IF(Data!R11-4>0,Data!R11-4,0)+N9 -> 0 | O10: =IF(Data!S11-4>0,Data!S11-4,0)+O9 -> 0 | P10: =IF(Data!T11-4>0,Data!T11-4,0)+P9 -> 0 | Q10: =IF(Data!U11-4>0,Data!U11-4,0)+Q9 -> 0 | R10: =IF(Data!V11-4>0,Data!V11-4,0)+R9 -> 0 | T10: =IF(Data!P11>0,Data!P11,0)+T9 -> 0 | U10: =IF(Data!Q11>0,Data!Q11,0)+U9 -> 0 | V10: =IF(Data!R11>0,Data!R11,0)+V9 -> 0 | W10: =IF(Data!S11>0,Data!S11,0)+W9 -> 0 | X10: =IF(Data!T11>0,Data!T11,0)+X9 -> 0 | Y10: =IF(Data!U11>0,Data!U11,0)+Y9 -> 0 | Z10: =IF(Data!V11>0,Data!V11,0)+Z9 -> 0
J11: 46031 | K11: 143 | L11: =IF(Data!P12-4>0,Data!P12-4,0)+L10 -> 0 | M11: =IF(Data!Q12-4>0,Data!Q12-4,0)+M10 -> 0 | N11: =IF(Data!R12-4>0,Data!R12-4,0)+N10 -> 0 | O11: =IF(Data!S12-4>0,Data!S12-4,0)+O10 -> 0 | P11: =IF(Data!T12-4>0,Data!T12-4,0)+P10 -> 0 | Q11: =IF(Data!U12-4>0,Data!U12-4,0)+Q10 -> 0 | R11: =IF(Data!V12-4>0,Data!V12-4,0)+R10 -> 0 | T11: =IF(Data!P12>0,Data!P12,0)+T10 -> 0 | U11: =IF(Data!Q12>0,Data!Q12,0)+U10 -> 0 | V11: =IF(Data!R12>0,Data!R12,0)+V10 -> 0 | W11: =IF(Data!S12>0,Data!S12,0)+W10 -> 0 | X11: =IF(Data!T12>0,Data!T12,0)+X10 -> 0 | Y11: =IF(Data!U12>0,Data!U12,0)+Y10 -> 0 | Z11: =IF(Data!V12>0,Data!V12,0)+Z10 -> 0
J12: 46032 | K12: 143 | L12: =IF(Data!P13-4>0,Data!P13-4,0)+L11 -> 0 | M12: =IF(Data!Q13-4>0,Data!Q13-4,0)+M11 -> 0 | N12: =IF(Data!R13-4>0,Data!R13-4,0)+N11 -> 0 | O12: =IF(Data!S13-4>0,Data!S13-4,0)+O11 -> 0 | P12: =IF(Data!T13-4>0,Data!T13-4,0)+P11 -> 0 | Q12: =IF(Data!U13-4>0,Data!U13-4,0)+Q11 -> 0 | R12: =IF(Data!V13-4>0,Data!V13-4,0)+R11 -> 0 | T12: =IF(Data!P13>0,Data!P13,0)+T11 -> 0 | U12: =IF(Data!Q13>0,Data!Q13,0)+U11 -> 0 | V12: =IF(Data!R13>0,Data!R13,0)+V11 -> 0 | W12: =IF(Data!S13>0,Data!S13,0)+W11 -> 0 | X12: =IF(Data!T13>0,Data!T13,0)+X11 -> 0 | Y12: =IF(Data!U13>0,Data!U13,0)+Y11 -> 0 | Z12: =IF(Data!V13>0,Data!V13,0)+Z11 -> 0
J13: 46033 | K13: 143 | L13: =IF(Data!P14-4>0,Data!P14-4,0)+L12 -> 0 | M13: =IF(Data!Q14-4>0,Data!Q14-4,0)+M12 -> 0 | N13: =IF(Data!R14-4>0,Data!R14-4,0)+N12 -> 0 | O13: =IF(Data!S14-4>0,Data!S14-4,0)+O12 -> 0 | P13: =IF(Data!T14-4>0,Data!T14-4,0)+P12 -> 0 | Q13: =IF(Data!U14-4>0,Data!U14-4,0)+Q12 -> 0 | R13: =IF(Data!V14-4>0,Data!V14-4,0)+R12 -> 0 | T13: =IF(Data!P14>0,Data!P14,0)+T12 -> 0 | U13: =IF(Data!Q14>0,Data!Q14,0)+U12 -> 0 | V13: =IF(Data!R14>0,Data!R14,0)+V12 -> 0 | W13: =IF(Data!S14>0,Data!S14,0)+W12 -> 0 | X13: =IF(Data!T14>0,Data!T14,0)+X12 -> 0 | Y13: =IF(Data!U14>0,Data!U14,0)+Y12 -> 0 | Z13: =IF(Data!V14>0,Data!V14,0)+Z12 -> 0
J14: 46034 | K14: 143 | L14: =IF(Data!P15-4>0,Data!P15-4,0)+L13 -> 0 | M14: =IF(Data!Q15-4>0,Data!Q15-4,0)+M13 -> 0 | N14: =IF(Data!R15-4>0,Data!R15-4,0)+N13 -> 0 | O14: =IF(Data!S15-4>0,Data!S15-4,0)+O13 -> 0 | P14: =IF(Data!T15-4>0,Data!T15-4,0)+P13 -> 0 | Q14: =IF(Data!U15-4>0,Data!U15-4,0)+Q13 -> 0 | R14: =IF(Data!V15-4>0,Data!V15-4,0)+R13 -> 0 | T14: =IF(Data!P15>0,Data!P15,0)+T13 -> 0 | U14: =IF(Data!Q15>0,Data!Q15,0)+U13 -> 0 | V14: =IF(Data!R15>0,Data!R15,0)+V13 -> 0 | W14: =IF(Data!S15>0,Data!S15,0)+W13 -> 0 | X14: =IF(Data!T15>0,Data!T15,0)+X13 -> 0 | Y14: =IF(Data!U15>0,Data!U15,0)+Y13 -> 0 | Z14: =IF(Data!V15>0,Data!V15,0)+Z13 -> 0
J15: 46035 | K15: 143 | L15: =IF(Data!P16-4>0,Data!P16-4,0)+L14 -> 0 | M15: =IF(Data!Q16-4>0,Data!Q16-4,0)+M14 -> 0 | N15: =IF(Data!R16-4>0,Data!R16-4,0)+N14 -> 0 | O15: =IF(Data!S16-4>0,Data!S16-4,0)+O14 -> 0 | P15: =IF(Data!T16-4>0,Data!T16-4,0)+P14 -> 0 | Q15: =IF(Data!U16-4>0,Data!U16-4,0)+Q14 -> 0 | R15: =IF(Data!V16-4>0,Data!V16-4,0)+R14 -> 0 | T15: =IF(Data!P16>0,Data!P16,0)+T14 -> 0 | U15: =IF(Data!Q16>0,Data!Q16,0)+U14 -> 0 | V15: =IF(Data!R16>0,Data!R16,0)+V14 -> 0 | W15: =IF(Data!S16>0,Data!S16,0)+W14 -> 0 | X15: =IF(Data!T16>0,Data!T16,0)+X14 -> 0 | Y15: =IF(Data!U16>0,Data!U16,0)+Y14 -> 0 | Z15: =IF(Data!V16>0,Data!V16,0)+Z14 -> 0
... J23: 46043 | K23: 143 | L23: =IF(Data!P24-4>0,Data!P24-4,0)+L22 -> 0 | M23: =IF(Data!Q24-4>0,Data!Q24-4,0)+M22 -> 0 | N23: =IF(Data!R24-4>0,Data!R24-4,0)+N22 -> 0 | O23: =IF(Data!S24-4>0,Data!S24-4,0)+O22 -> 0 | P23: =IF(Data!T24-4>0,Data!T24-4,0)+P22 -> 0 | Q23: =IF(Data!U24-4>0,Data!U24-4,0)+Q22 -> 0 | R23: =IF(Data!V24-4>0,Data!V24-4,0)+R22 -> 0 | T23: =IF(Data!P24>0,Data!P24,0)+T22 -> 0 | U23: =IF(Data!Q24>0,Data!Q24,0)+U22 -> 0 | V23: =IF(Data!R24>0,Data!R24,0)+V22 -> 0 | W23: =IF(Data!S24>0,Data!S24,0)+W22 -> 0 | X23: =IF(Data!T24>0,Data!T24,0)+X22 -> 0 | Y23: =IF(Data!U24>0,Data!U24,0)+Y22 -> 0 | Z23: =IF(Data!V24>0,Data!V24,0)+Z22 -> 0
A24: Base 4°C | B24: =L2 -> #NAME? | C24: =M2 -> #NAME? | D24: =N2 -> #NAME? | E24: =O2 -> #NAME? | F24: =P2 -> #NAME? | G24: =Q2 -> #NAME? | H24: =R2 -> #NAME? | J24: 46044 | K24: 143 | L24: =IF(Data!P25-4>0,Data!P25-4,0)+L23 -> 0 | M24: =IF(Data!Q25-4>0,Data!Q25-4,0)+M23 -> 0 | N24: =IF(Data!R25-4>0,Data!R25-4,0)+N23 -> 0 | O24: =IF(Data!S25-4>0,Data!S25-4,0)+O23 -> 0 | P24: =IF(Data!T25-4>0,Data!T25-4,0)+P23 -> 0 | Q24: =IF(Data!U25-4>0,Data!U25-4,0)+Q23 -> 0 | R24: =IF(Data!V25-4>0,Data!V25-4,0)+R23 -> 0 | T24: =IF(Data!P25>0,Data!P25,0)+T23 -> 0 | U24: =IF(Data!Q25>0,Data!Q25,0)+U23 -> 0 | V24: =IF(Data!R25>0,Data!R25,0)+V23 -> 0 | W24: =IF(Data!S25>0,Data!S25,0)+W23 -> 0 | X24: =IF(Data!T25>0,Data!T25,0)+X23 -> 0 | Y24: =IF(Data!U25>0,Data!U25,0)+Y23 -> 0 | Z24: =IF(Data!V25>0,Data!V25,0)+Z23 -> 0
A25: Cumul de Température (°C) | B25: =L92 -> 0 | C25: =M92 -> 0 | D25: =N92 -> 0 | E25: =O92 -> 0 | F25: =P92 -> 0 | G25: =Q92 -> 0 | H25: =R92 -> 0 | J25: 46045 | K25: 143 | L25: =IF(Data!P26-4>0,Data!P26-4,0)+L24 -> 0 | M25: =IF(Data!Q26-4>0,Data!Q26-4,0)+M24 -> 0 | N25: =IF(Data!R26-4>0,Data!R26-4,0)+N24 -> 0 | O25: =IF(Data!S26-4>0,Data!S26-4,0)+O24 -> 0 | P25: =IF(Data!T26-4>0,Data!T26-4,0)+P24 -> 0 | Q25: =IF(Data!U26-4>0,Data!U26-4,0)+Q24 -> 0 | R25: =IF(Data!V26-4>0,Data!V26-4,0)+R24 -> 0 | T25: =IF(Data!P26>0,Data!P26,0)+T24 -> 0 | U25: =IF(Data!Q26>0,Data!Q26,0)+U24 -> 0 | V25: =IF(Data!R26>0,Data!R26,0)+V24 -> 0 | W25: =IF(Data!S26>0,Data!S26,0)+W24 -> 0 | X25: =IF(Data!T26>0,Data!T26,0)+X24 -> 0 | Y25: =IF(Data!U26>0,Data!U26,0)+Y24 -> 0 | Z25: =IF(Data!V26>0,Data!V26,0)+Z24 -> 0
J26: 46046 | K26: 143 | L26: =IF(Data!P27-4>0,Data!P27-4,0)+L25 -> 0 | M26: =IF(Data!Q27-4>0,Data!Q27-4,0)+M25 -> 0 | N26: =IF(Data!R27-4>0,Data!R27-4,0)+N25 -> 0 | O26: =IF(Data!S27-4>0,Data!S27-4,0)+O25 -> 0 | P26: =IF(Data!T27-4>0,Data!T27-4,0)+P25 -> 0 | Q26: =IF(Data!U27-4>0,Data!U27-4,0)+Q25 -> 0 | R26: =IF(Data!V27-4>0,Data!V27-4,0)+R25 -> 0 | T26: =IF(Data!P27>0,Data!P27,0)+T25 -> 0 | U26: =IF(Data!Q27>0,Data!Q27,0)+U25 -> 0 | V26: =IF(Data!R27>0,Data!R27,0)+V25 -> 0 | W26: =IF(Data!S27>0,Data!S27,0)+W25 -> 0 | X26: =IF(Data!T27>0,Data!T27,0)+X25 -> 0 | Y26: =IF(Data!U27>0,Data!U27,0)+Y25 -> 0 | Z26: =IF(Data!V27>0,Data!V27,0)+Z25 -> 0
A27: Base 0°C | B27: =T2 -> #NAME? | C27: =U2 -> #NAME? | D27: =V2 -> #NAME? | E27: =W2 -> #NAME? | F27: =X2 -> #NAME? | G27: =Y2 -> #NAME? | H27: =Z2 -> #NAME? | J27: 46047 | K27: 143 | L27: =IF(Data!P28-4>0,Data!P28-4,0)+L26 -> 0 | M27: =IF(Data!Q28-4>0,Data!Q28-4,0)+M26 -> 0 | N27: =IF(Data!R28-4>0,Data!R28-4,0)+N26 -> 0 | O27: =IF(Data!S28-4>0,Data!S28-4,0)+O26 -> 0 | P27: =IF(Data!T28-4>0,Data!T28-4,0)+P26 -> 0 | Q27: =IF(Data!U28-4>0,Data!U28-4,0)+Q26 -> 0 | R27: =IF(Data!V28-4>0,Data!V28-4,0)+R26 -> 0 | T27: =IF(Data!P28>0,Data!P28,0)+T26 -> 0 | U27: =IF(Data!Q28>0,Data!Q28,0)+U26 -> 0 | V27: =IF(Data!R28>0,Data!R28,0)+V26 -> 0 | W27: =IF(Data!S28>0,Data!S28,0)+W26 -> 0 | X27: =IF(Data!T28>0,Data!T28,0)+X26 -> 0 | Y27: =IF(Data!U28>0,Data!U28,0)+Y26 -> 0 | Z27: =IF(Data!V28>0,Data!V28,0)+Z26 -> 0
A28: Cumul de Température (°C) | B28: =T92 -> 0 | C28: =U92 -> 0 | D28: =V92 -> 0 | E28: =W92 -> 0 | F28: =X92 -> 0 | G28: =Y92 -> 0 | H28: =Z92 -> 0 | J28: 46048 | K28: 143 | L28: =IF(Data!P29-4>0,Data!P29-4,0)+L27 -> 0 | M28: =IF(Data!Q29-4>0,Data!Q29-4,0)+M27 -> 0 | N28: =IF(Data!R29-4>0,Data!R29-4,0)+N27 -> 0 | O28: =IF(Data!S29-4>0,Data!S29-4,0)+O27 -> 0 | P28: =IF(Data!T29-4>0,Data!T29-4,0)+P27 -> 0 | Q28: =IF(Data!U29-4>0,Data!U29-4,0)+Q27 -> 0 | R28: =IF(Data!V29-4>0,Data!V29-4,0)+R27 -> 0 | T28: =IF(Data!P29>0,Data!P29,0)+T27 -> 0 | U28: =IF(Data!Q29>0,Data!Q29,0)+U27 -> 0 | V28: =IF(Data!R29>0,Data!R29,0)+V27 -> 0 | W28: =IF(Data!S29>0,Data!S29,0)+W27 -> 0 | X28: =IF(Data!T29>0,Data!T29,0)+X27 -> 0 | Y28: =IF(Data!U29>0,Data!U29,0)+Y27 -> 0 | Z28: =IF(Data!V29>0,Data!V29,0)+Z27 -> 0
J29: 46049 | K29: 143 | L29: =IF(Data!P30-4>0,Data!P30-4,0)+L28 -> 0 | M29: =IF(Data!Q30-4>0,Data!Q30-4,0)+M28 -> 0 | N29: =IF(Data!R30-4>0,Data!R30-4,0)+N28 -> 0 | O29: =IF(Data!S30-4>0,Data!S30-4,0)+O28 -> 0 | P29: =IF(Data!T30-4>0,Data!T30-4,0)+P28 -> 0 | Q29: =IF(Data!U30-4>0,Data!U30-4,0)+Q28 -> 0 | R29: =IF(Data!V30-4>0,Data!V30-4,0)+R28 -> 0 | T29: =IF(Data!P30>0,Data!P30,0)+T28 -> 0 | U29: =IF(Data!Q30>0,Data!Q30,0)+U28 -> 0 | V29: =IF(Data!R30>0,Data!R30,0)+V28 -> 0 | W29: =IF(Data!S30>0,Data!S30,0)+W28 -> 0 | X29: =IF(Data!T30>0,Data!T30,0)+X28 -> 0 | Y29: =IF(Data!U30>0,Data!U30,0)+Y28 -> 0 | Z29: =IF(Data!V30>0,Data!V30,0)+Z28 -> 0
J30: 46050 | K30: 143 | L30: =IF(Data!P31-4>0,Data!P31-4,0)+L29 -> 0 | M30: =IF(Data!Q31-4>0,Data!Q31-4,0)+M29 -> 0 | N30: =IF(Data!R31-4>0,Data!R31-4,0)+N29 -> 0 | O30: =IF(Data!S31-4>0,Data!S31-4,0)+O29 -> 0 | P30: =IF(Data!T31-4>0,Data!T31-4,0)+P29 -> 0 | Q30: =IF(Data!U31-4>0,Data!U31-4,0)+Q29 -> 0 | R30: =IF(Data!V31-4>0,Data!V31-4,0)+R29 -> 0 | T30: =IF(Data!P31>0,Data!P31,0)+T29 -> 0 | U30: =IF(Data!Q31>0,Data!Q31,0)+U29 -> 0 | V30: =IF(Data!R31>0,Data!R31,0)+V29 -> 0 | W30: =IF(Data!S31>0,Data!S31,0)+W29 -> 0 | X30: =IF(Data!T31>0,Data!T31,0)+X29 -> 0 | Y30: =IF(Data!U31>0,Data!U31,0)+Y29 -> 0 | Z30: =IF(Data!V31>0,Data!V31,0)+Z29 -> 0
J31: 46051 | K31: 143 | L31: =IF(Data!P32-4>0,Data!P32-4,0)+L30 -> 0 | M31: =IF(Data!Q32-4>0,Data!Q32-4,0)+M30 -> 0 | N31: =IF(Data!R32-4>0,Data!R32-4,0)+N30 -> 0 | O31: =IF(Data!S32-4>0,Data!S32-4,0)+O30 -> 0 | P31: =IF(Data!T32-4>0,Data!T32-4,0)+P30 -> 0 | Q31: =IF(Data!U32-4>0,Data!U32-4,0)+Q30 -> 0 | R31: =IF(Data!V32-4>0,Data!V32-4,0)+R30 -> 0 | T31: =IF(Data!P32>0,Data!P32,0)+T30 -> 0 | U31: =IF(Data!Q32>0,Data!Q32,0)+U30 -> 0 | V31: =IF(Data!R32>0,Data!R32,0)+V30 -> 0 | W31: =IF(Data!S32>0,Data!S32,0)+W30 -> 0 | X31: =IF(Data!T32>0,Data!T32,0)+X30 -> 0 | Y31: =IF(Data!U32>0,Data!U32,0)+Y30 -> 0 | Z31: =IF(Data!V32>0,Data!V32,0)+Z30 -> 0
J32: 46052 | K32: 143 | L32: =IF(Data!P33-4>0,Data!P33-4,0)+L31 -> 0 | M32: =IF(Data!Q33-4>0,Data!Q33-4,0)+M31 -> 0 | N32: =IF(Data!R33-4>0,Data!R33-4,0)+N31 -> 0 | O32: =IF(Data!S33-4>0,Data!S33-4,0)+O31 -> 0 | P32: =IF(Data!T33-4>0,Data!T33-4,0)+P31 -> 0 | Q32: =IF(Data!U33-4>0,Data!U33-4,0)+Q31 -> 0 | R32: =IF(Data!V33-4>0,Data!V33-4,0)+R31 -> 0 | T32: =IF(Data!P33>0,Data!P33,0)+T31 -> 0 | U32: =IF(Data!Q33>0,Data!Q33,0)+U31 -> 0 | V32: =IF(Data!R33>0,Data!R33,0)+V31 -> 0 | W32: =IF(Data!S33>0,Data!S33,0)+W31 -> 0 | X32: =IF(Data!T33>0,Data!T33,0)+X31 -> 0 | Y32: =IF(Data!U33>0,Data!U33,0)+Y31 -> 0 | Z32: =IF(Data!V33>0,Data!V33,0)+Z31 -> 0
J33: 46053 | K33: 143 | L33: =IF(Data!P34-4>0,Data!P34-4,0)+L32 -> 0 | M33: =IF(Data!Q34-4>0,Data!Q34-4,0)+M32 -> 0 | N33: =IF(Data!R34-4>0,Data!R34-4,0)+N32 -> 0 | O33: =IF(Data!S34-4>0,Data!S34-4,0)+O32 -> 0 | P33: =IF(Data!T34-4>0,Data!T34-4,0)+P32 -> 0 | Q33: =IF(Data!U34-4>0,Data!U34-4,0)+Q32 -> 0 | R33: =IF(Data!V34-4>0,Data!V34-4,0)+R32 -> 0 | T33: =IF(Data!P34>0,Data!P34,0)+T32 -> 0 | U33: =IF(Data!Q34>0,Data!Q34,0)+U32 -> 0 | V33: =IF(Data!R34>0,Data!R34,0)+V32 -> 0 | W33: =IF(Data!S34>0,Data!S34,0)+W32 -> 0 | X33: =IF(Data!T34>0,Data!T34,0)+X32 -> 0 | Y33: =IF(Data!U34>0,Data!U34,0)+Y32 -> 0 | Z33: =IF(Data!V34>0,Data!V34,0)+Z32 -> 0
J34: 46054 | K34: 143 | L34: =IF(Data!P35-4>0,Data!P35-4,0)+L33 -> 0 | M34: =IF(Data!Q35-4>0,Data!Q35-4,0)+M33 -> 0 | N34: =IF(Data!R35-4>0,Data!R35-4,0)+N33 -> 0 | O34: =IF(Data!S35-4>0,Data!S35-4,0)+O33 -> 0 | P34: =IF(Data!T35-4>0,Data!T35-4,0)+P33 -> 0 | Q34: =IF(Data!U35-4>0,Data!U35-4,0)+Q33 -> 0 | R34: =IF(Data!V35-4>0,Data!V35-4,0)+R33 -> 0 | T34: =IF(Data!P35>0,Data!P35,0)+T33 -> 0 | U34: =IF(Data!Q35>0,Data!Q35,0)+U33 -> 0 | V34: =IF(Data!R35>0,Data!R35,0)+V33 -> 0 | W34: =IF(Data!S35>0,Data!S35,0)+W33 -> 0 | X34: =IF(Data!T35>0,Data!T35,0)+X33 -> 0 | Y34: =IF(Data!U35>0,Data!U35,0)+Y33 -> 0 | Z34: =IF(Data!V35>0,Data!V35,0)+Z33 -> 0
J35: 46055 | K35: 143 | L35: =IF(Data!P36-4>0,Data!P36-4,0)+L34 -> 0 | M35: =IF(Data!Q36-4>0,Data!Q36-4,0)+M34 -> 0 | N35: =IF(Data!R36-4>0,Data!R36-4,0)+N34 -> 0 | O35: =IF(Data!S36-4>0,Data!S36-4,0)+O34 -> 0 | P35: =IF(Data!T36-4>0,Data!T36-4,0)+P34 -> 0 | Q35: =IF(Data!U36-4>0,Data!U36-4,0)+Q34 -> 0 | R35: =IF(Data!V36-4>0,Data!V36-4,0)+R34 -> 0 | T35: =IF(Data!P36>0,Data!P36,0)+T34 -> 0 | U35: =IF(Data!Q36>0,Data!Q36,0)+U34 -> 0 | V35: =IF(Data!R36>0,Data!R36,0)+V34 -> 0 | W35: =IF(Data!S36>0,Data!S36,0)+W34 -> 0 | X35: =IF(Data!T36>0,Data!T36,0)+X34 -> 0 | Y35: =IF(Data!U36>0,Data!U36,0)+Y34 -> 0 | Z35: =IF(Data!V36>0,Data!V36,0)+Z34 -> 0
J36: 46056 | K36: 143 | L36: =IF(Data!P37-4>0,Data!P37-4,0)+L35 -> 0 | M36: =IF(Data!Q37-4>0,Data!Q37-4,0)+M35 -> 0 | N36: =IF(Data!R37-4>0,Data!R37-4,0)+N35 -> 0 | O36: =IF(Data!S37-4>0,Data!S37-4,0)+O35 -> 0 | P36: =IF(Data!T37-4>0,Data!T37-4,0)+P35 -> 0 | Q36: =IF(Data!U37-4>0,Data!U37-4,0)+Q35 -> 0 | R36: =IF(Data!V37-4>0,Data!V37-4,0)+R35 -> 0 | T36: =IF(Data!P37>0,Data!P37,0)+T35 -> 0 | U36: =IF(Data!Q37>0,Data!Q37,0)+U35 -> 0 | V36: =IF(Data!R37>0,Data!R37,0)+V35 -> 0 | W36: =IF(Data!S37>0,Data!S37,0)+W35 -> 0 | X36: =IF(Data!T37>0,Data!T37,0)+X35 -> 0 | Y36: =IF(Data!U37>0,Data!U37,0)+Y35 -> 0 | Z36: =IF(Data!V37>0,Data!V37,0)+Z35 -> 0
J37: 46057 | K37: 143 | L37: =IF(Data!P38-4>0,Data!P38-4,0)+L36 -> 0 | M37: =IF(Data!Q38-4>0,Data!Q38-4,0)+M36 -> 0 | N37: =IF(Data!R38-4>0,Data!R38-4,0)+N36 -> 0 | O37: =IF(Data!S38-4>0,Data!S38-4,0)+O36 -> 0 | P37: =IF(Data!T38-4>0,Data!T38-4,0)+P36 -> 0 | Q37: =IF(Data!U38-4>0,Data!U38-4,0)+Q36 -> 0 | R37: =IF(Data!V38-4>0,Data!V38-4,0)+R36 -> 0 | T37: =IF(Data!P38>0,Data!P38,0)+T36 -> 0 | U37: =IF(Data!Q38>0,Data!Q38,0)+U36 -> 0 | V37: =IF(Data!R38>0,Data!R38,0)+V36 -> 0 | W37: =IF(Data!S38>0,Data!S38,0)+W36 -> 0 | X37: =IF(Data!T38>0,Data!T38,0)+X36 -> 0 | Y37: =IF(Data!U38>0,Data!U38,0)+Y36 -> 0 | Z37: =IF(Data!V38>0,Data!V38,0)+Z36 -> 0
J38: 46058 | K38: 143 | L38: =IF(Data!P39-4>0,Data!P39-4,0)+L37 -> 0 | M38: =IF(Data!Q39-4>0,Data!Q39-4,0)+M37 -> 0 | N38: =IF(Data!R39-4>0,Data!R39-4,0)+N37 -> 0 | O38: =IF(Data!S39-4>0,Data!S39-4,0)+O37 -> 0 | P38: =IF(Data!T39-4>0,Data!T39-4,0)+P37 -> 0 | Q38: =IF(Data!U39-4>0,Data!U39-4,0)+Q37 -> 0 | R38: =IF(Data!V39-4>0,Data!V39-4,0)+R37 -> 0 | T38: =IF(Data!P39>0,Data!P39,0)+T37 -> 0 | U38: =IF(Data!Q39>0,Data!Q39,0)+U37 -> 0 | V38: =IF(Data!R39>0,Data!R39,0)+V37 -> 0 | W38: =IF(Data!S39>0,Data!S39,0)+W37 -> 0 | X38: =IF(Data!T39>0,Data!T39,0)+X37 -> 0 | Y38: =IF(Data!U39>0,Data!U39,0)+Y37 -> 0 | Z38: =IF(Data!V39>0,Data!V39,0)+Z37 -> 0
J39: 46059 | K39: 143 | L39: =IF(Data!P40-4>0,Data!P40-4,0)+L38 -> 0 | M39: =IF(Data!Q40-4>0,Data!Q40-4,0)+M38 -> 0 | N39: =IF(Data!R40-4>0,Data!R40-4,0)+N38 -> 0 | O39: =IF(Data!S40-4>0,Data!S40-4,0)+O38 -> 0 | P39: =IF(Data!T40-4>0,Data!T40-4,0)+P38 -> 0 | Q39: =IF(Data!U40-4>0,Data!U40-4,0)+Q38 -> 0 | R39: =IF(Data!V40-4>0,Data!V40-4,0)+R38 -> 0 | T39: =IF(Data!P40>0,Data!P40,0)+T38 -> 0 | U39: =IF(Data!Q40>0,Data!Q40,0)+U38 -> 0 | V39: =IF(Data!R40>0,Data!R40,0)+V38 -> 0 | W39: =IF(Data!S40>0,Data!S40,0)+W38 -> 0 | X39: =IF(Data!T40>0,Data!T40,0)+X38 -> 0 | Y39: =IF(Data!U40>0,Data!U40,0)+Y38 -> 0 | Z39: =IF(Data!V40>0,Data!V40,0)+Z38 -> 0
J40: 46060 | K40: 143 | L40: =IF(Data!P41-4>0,Data!P41-4,0)+L39 -> 0 | M40: =IF(Data!Q41-4>0,Data!Q41-4,0)+M39 -> 0 | N40: =IF(Data!R41-4>0,Data!R41-4,0)+N39 -> 0 | O40: =IF(Data!S41-4>0,Data!S41-4,0)+O39 -> 0 | P40: =IF(Data!T41-4>0,Data!T41-4,0)+P39 -> 0 | Q40: =IF(Data!U41-4>0,Data!U41-4,0)+Q39 -> 0 | R40: =IF(Data!V41-4>0,Data!V41-4,0)+R39 -> 0 | T40: =IF(Data!P41>0,Data!P41,0)+T39 -> 0 | U40: =IF(Data!Q41>0,Data!Q41,0)+U39 -> 0 | V40: =IF(Data!R41>0,Data!R41,0)+V39 -> 0 | W40: =IF(Data!S41>0,Data!S41,0)+W39 -> 0 | X40: =IF(Data!T41>0,Data!T41,0)+X39 -> 0 | Y40: =IF(Data!U41>0,Data!U41,0)+Y39 -> 0 | Z40: =IF(Data!V41>0,Data!V41,0)+Z39 -> 0
... J92: 46112 | K92: 143 | L92: =IF(Data!P93-4>0,Data!P93-4,0)+L91 -> 0 | M92: =IF(Data!Q93-4>0,Data!Q93-4,0)+M91 -> 0 | N92: =IF(Data!R93-4>0,Data!R93-4,0)+N91 -> 0 | O92: =IF(Data!S93-4>0,Data!S93-4,0)+O91 -> 0 | P92: =IF(Data!T93-4>0,Data!T93-4,0)+P91 -> 0 | Q92: =IF(Data!U93-4>0,Data!U93-4,0)+Q91 -> 0 | R92: =IF(Data!V93-4>0,Data!V93-4,0)+R91 -> 0 | T92: =IF(Data!P93>0,Data!P93,0)+T91 -> 0 | U92: =IF(Data!Q93>0,Data!Q93,0)+U91 -> 0 | V92: =IF(Data!R93>0,Data!R93,0)+V91 -> 0 | W92: =IF(Data!S93>0,Data!S93,0)+W91 -> 0 | X92: =IF(Data!T93>0,Data!T93,0)+X91 -> 0 | Y92: =IF(Data!U93>0,Data!U93,0)+Y91 -> 0 | Z92: =IF(Data!V93>0,Data!V93,0)+Z91 -> 0

Sheet Nord
J1: Département | L1: =Data!O3 -> 0 | T1: =L1 -> 0
J2: Ville | K2: Seuil (143°J) | L2: =_xlfn.CONCAT(Data!O1," (",Data!O2,")") -> #NAME? | T2: =L2 -> #NAME?
J3: 46023 | K3: 143 | L3: =IF(Data!O4-4>0,Data!O4-4,0) -> 0 | T3: =IF(Data!O4>0,Data!O4,0) -> 0
J4: 46024 | K4: 143 | L4: =IF(Data!O5-4>0,Data!O5-4,0)+L3 -> 0 | T4: =IF(Data!O5>0,Data!O5,0)+T3 -> 0
J5: 46025 | K5: 143 | L5: =IF(Data!O6-4>0,Data!O6-4,0)+L4 -> 0 | T5: =IF(Data!O6>0,Data!O6,0)+T4 -> 0
J6: 46026 | K6: 143 | L6: =IF(Data!O7-4>0,Data!O7-4,0)+L5 -> 0 | T6: =IF(Data!O7>0,Data!O7,0)+T5 -> 0
J7: 46027 | K7: 143 | L7: =IF(Data!O8-4>0,Data!O8-4,0)+L6 -> 0 | T7: =IF(Data!O8>0,Data!O8,0)+T6 -> 0
J8: 46028 | K8: 143 | L8: =IF(Data!O9-4>0,Data!O9-4,0)+L7 -> 0 | T8: =IF(Data!O9>0,Data!O9,0)+T7 -> 0
J9: 46029 | K9: 143 | L9: =IF(Data!O10-4>0,Data!O10-4,0)+L8 -> 0 | T9: =IF(Data!O10>0,Data!O10,0)+T8 -> 0
J10: 46030 | K10: 143 | L10: =IF(Data!O11-4>0,Data!O11-4,0)+L9 -> 0 | T10: =IF(Data!O11>0,Data!O11,0)+T9 -> 0
J11: 46031 | K11: 143 | L11: =IF(Data!O12-4>0,Data!O12-4,0)+L10 -> 0 | T11: =IF(Data!O12>0,Data!O12,0)+T10 -> 0
J12: 46032 | K12: 143 | L12: =IF(Data!O13-4>0,Data!O13-4,0)+L11 -> 0 | T12: =IF(Data!O13>0,Data!O13,0)+T11 -> 0
J13: 46033 | K13: 143 | L13: =IF(Data!O14-4>0,Data!O14-4,0)+L12 -> 0 | T13: =IF(Data!O14>0,Data!O14,0)+T12 -> 0
J14: 46034 | K14: 143 | L14: =IF(Data!O15-4>0,Data!O15-4,0)+L13 -> 0 | T14: =IF(Data!O15>0,Data!O15,0)+T13 -> 0
J15: 46035 | K15: 143 | L15: =IF(Data!O16-4>0,Data!O16-4,0)+L14 -> 0 | T15: =IF(Data!O16>0,Data!O16,0)+T14 -> 0
... J23: 46043 | K23: 143 | L23: =IF(Data!O24-4>0,Data!O24-4,0)+L22 -> 0 | T23: =IF(Data!O24>0,Data!O24,0)+T22 -> 0
A24: Base 4°C | B24: =L2 -> #NAME? | C24: =N2 -> 0 | D24: =O2 -> 0 | E24: =P2 -> 0 | F24: =Q2 -> 0 | G24: =R2 -> 0 | H24: =S2 -> 0 | J24: 46044 | K24: 143 | L24: =IF(Data!O25-4>0,Data!O25-4,0)+L23 -> 0 | T24: =IF(Data!O25>0,Data!O25,0)+T23 -> 0
A25: Cumul de Température (°C) | B25: =L92 -> 0 | C25: =N92 -> 0 | D25: =O92 -> 0 | E25: =P92 -> 0 | F25: =Q92 -> 0 | G25: =R92 -> 0 | H25: =S92 -> 0 | J25: 46045 | K25: 143 | L25: =IF(Data!O26-4>0,Data!O26-4,0)+L24 -> 0 | T25: =IF(Data!O26>0,Data!O26,0)+T24 -> 0
J26: 46046 | K26: 143 | L26: =IF(Data!O27-4>0,Data!O27-4,0)+L25 -> 0 | T26: =IF(Data!O27>0,Data!O27,0)+T25 -> 0
A27: Base 0°C | B27: =T2 -> #NAME? | C27: =V2 -> 0 | D27: =W2 -> 0 | E27: =X2 -> 0 | F27: =Y2 -> 0 | G27: =Z2 -> 0 | H27: =AA2 -> 0 | J27: 46047 | K27: 143 | L27: =IF(Data!O28-4>0,Data!O28-4,0)+L26 -> 0 | T27: =IF(Data!O28>0,Data!O28,0)+T26 -> 0
A28: Cumul de Température (°C) | B28: =T92 -> 0 | C28: =V92 -> 0 | D28: =W92 -> 0 | E28: =X92 -> 0 | F28: =Y92 -> 0 | G28: =Z92 -> 0 | H28: =AA92 -> 0 | J28: 46048 | K28: 143 | L28: =IF(Data!O29-4>0,Data!O29-4,0)+L27 -> 0 | T28: =IF(Data!O29>0,Data!O29,0)+T27 -> 0
J29: 46049 | K29: 143 | L29: =IF(Data!O30-4>0,Data!O30-4,0)+L28 -> 0 | T29: =IF(Data!O30>0,Data!O30,0)+T28 -> 0
J30: 46050 | K30: 143 | L30: =IF(Data!O31-4>0,Data!O31-4,0)+L29 -> 0 | T30: =IF(Data!O31>0,Data!O31,0)+T29 -> 0
J31: 46051 | K31: 143 | L31: =IF(Data!O32-4>0,Data!O32-4,0)+L30 -> 0 | T31: =IF(Data!O32>0,Data!O32,0)+T30 -> 0
J32: 46052 | K32: 143 | L32: =IF(Data!O33-4>0,Data!O33-4,0)+L31 -> 0 | T32: =IF(Data!O33>0,Data!O33,0)+T31 -> 0
J33: 46053 | K33: 143 | L33: =IF(Data!O34-4>0,Data!O34-4,0)+L32 -> 0 | T33: =IF(Data!O34>0,Data!O34,0)+T32 -> 0
J34: 46054 | K34: 143 | L34: =IF(Data!O35-4>0,Data!O35-4,0)+L33 -> 0 | T34: =IF(Data!O35>0,Data!O35,0)+T33 -> 0
J35: 46055 | K35: 143 | L35: =IF(Data!O36-4>0,Data!O36-4,0)+L34 -> 0 | T35: =IF(Data!O36>0,Data!O36,0)+T34 -> 0
J36: 46056 | K36: 143 | L36: =IF(Data!O37-4>0,Data!O37-4,0)+L35 -> 0 | T36: =IF(Data!O37>0,Data!O37,0)+T35 -> 0
J37: 46057 | K37: 143 | L37: =IF(Data!O38-4>0,Data!O38-4,0)+L36 -> 0 | T37: =IF(Data!O38>0,Data!O38,0)+T36 -> 0
J38: 46058 | K38: 143 | L38: =IF(Data!O39-4>0,Data!O39-4,0)+L37 -> 0 | T38: =IF(Data!O39>0,Data!O39,0)+T37 -> 0
J39: 46059 | K39: 143 | L39: =IF(Data!O40-4>0,Data!O40-4,0)+L38 -> 0 | T39: =IF(Data!O40>0,Data!O40,0)+T38 -> 0
J40: 46060 | K40: 143 | L40: =IF(Data!O41-4>0,Data!O41-4,0)+L39 -> 0 | T40: =IF(Data!O41>0,Data!O41,0)+T39 -> 0
... J92: 46112 | K92: 143 | L92: =IF(Data!O93-4>0,Data!O93-4,0)+L91 -> 0 | T92: =IF(Data!O93>0,Data!O93,0)+T91 -> 0

Sheet Sud
J1: Département | L1: =Data!J3 -> 0 | M1: =Data!K3 -> 0 | N1: =Data!L3 -> 0 | O1: =Data!M3 -> 0 | P1: =Data!N3 -> 0 | T1: =L1 -> 0 | U1: =M1 -> 0 | V1: =N1 -> 0 | W1: =O1 -> 0 | X1: =P1 -> 0
J2: Ville | K2: Seuil (143°J) | L2: =_xlfn.CONCAT(Data!J1," (",Data!J2,")") -> #NAME? | M2: =_xlfn.CONCAT(Data!K1," (",Data!K2,")") -> #NAME? | N2: =_xlfn.CONCAT(Data!L1," (",Data!L2,")") -> #NAME? | O2: =_xlfn.CONCAT(Data!M1," (",Data!M2,")") -> #NAME? | P2: =_xlfn.CONCAT(Data!N1," (",Data!N2,")") -> #NAME? | T2: =L2 -> #NAME? | U2: =M2 -> #NAME? | V2: =N2 -> #NAME? | W2: =O2 -> #NAME? | X2: =P2 -> #NAME?
J3: 46023 | K3: 143 | L3: =IF(Data!J4-4>0,Data!J4-4,0) -> 0 | M3: =IF(Data!K4-4>0,Data!K4-4,0) -> 0 | N3: =IF(Data!L4-4>0,Data!L4-4,0) -> 0 | O3: =IF(Data!M4-4>0,Data!M4-4,0) -> 0 | P3: =IF(Data!N4-4>0,Data!N4-4,0) -> 0 | T3: =IF(Data!J4>0,Data!J4,0) -> 0 | U3: =IF(Data!K4>0,Data!K4,0) -> 0 | V3: =IF(Data!L4>0,Data!L4,0) -> 0 | W3: =IF(Data!M4>0,Data!M4,0) -> 0 | X3: =IF(Data!N4>0,Data!N4,0) -> 0
J4: 46024 | K4: 143 | L4: =IF(Data!J5-4>0,Data!J5-4,0)+L3 -> 0 | M4: =IF(Data!K5-4>0,Data!K5-4,0)+M3 -> 0 | N4: =IF(Data!L5-4>0,Data!L5-4,0)+N3 -> 0 | O4: =IF(Data!M5-4>0,Data!M5-4,0)+O3 -> 0 | P4: =IF(Data!N5-4>0,Data!N5-4,0)+P3 -> 0 | T4: =IF(Data!J5>0,Data!J5,0)+T3 -> 0 | U4: =IF(Data!K5>0,Data!K5,0)+U3 -> 0 | V4: =IF(Data!L5>0,Data!L5,0)+V3 -> 0 | W4: =IF(Data!M5>0,Data!M5,0)+W3 -> 0 | X4: =IF(Data!N5>0,Data!N5,0)+X3 -> 0
J5: 46025 | K5: 143 | L5: =IF(Data!J6-4>0,Data!J6-4,0)+L4 -> 0 | M5: =IF(Data!K6-4>0,Data!K6-4,0)+M4 -> 0 | N5: =IF(Data!L6-4>0,Data!L6-4,0)+N4 -> 0 | O5: =IF(Data!M6-4>0,Data!M6-4,0)+O4 -> 0 | P5: =IF(Data!N6-4>0,Data!N6-4,0)+P4 -> 0 | T5: =IF(Data!J6>0,Data!J6,0)+T4 -> 0 | U5: =IF(Data!K6>0,Data!K6,0)+U4 -> 0 | V5: =IF(Data!L6>0,Data!L6,0)+V4 -> 0 | W5: =IF(Data!M6>0,Data!M6,0)+W4 -> 0 | X5: =IF(Data!N6>0,Data!N6,0)+X4 -> 0
J6: 46026 | K6: 143 | L6: =IF(Data!J7-4>0,Data!J7-4,0)+L5 -> 0 | M6: =IF(Data!K7-4>0,Data!K7-4,0)+M5 -> 0 | N6: =IF(Data!L7-4>0,Data!L7-4,0)+N5 -> 0 | O6: =IF(Data!M7-4>0,Data!M7-4,0)+O5 -> 0 | P6: =IF(Data!N7-4>0,Data!N7-4,0)+P5 -> 0 | T6: =IF(Data!J7>0,Data!J7,0)+T5 -> 0 | U6: =IF(Data!K7>0,Data!K7,0)+U5 -> 0 | V6: =IF(Data!L7>0,Data!L7,0)+V5 -> 0 | W6: =IF(Data!M7>0,Data!M7,0)+W5 -> 0 | X6: =IF(Data!N7>0,Data!N7,0)+X5 -> 0
J7: 46027 | K7: 143 | L7: =IF(Data!J8-4>0,Data!J8-4,0)+L6 -> 0 | M7: =IF(Data!K8-4>0,Data!K8-4,0)+M6 -> 0 | N7: =IF(Data!L8-4>0,Data!L8-4,0)+N6 -> 0 | O7: =IF(Data!M8-4>0,Data!M8-4,0)+O6 -> 0 | P7: =IF(Data!N8-4>0,Data!N8-4,0)+P6 -> 0 | T7: =IF(Data!J8>0,Data!J8,0)+T6 -> 0 | U7: =IF(Data!K8>0,Data!K8,0)+U6 -> 0 | V7: =IF(Data!L8>0,Data!L8,0)+V6 -> 0 | W7: =IF(Data!M8>0,Data!M8,0)+W6 -> 0 | X7: =IF(Data!N8>0,Data!N8,0)+X6 -> 0
J8: 46028 | K8: 143 | L8: =IF(Data!J9-4>0,Data!J9-4,0)+L7 -> 0 | M8: =IF(Data!K9-4>0,Data!K9-4,0)+M7 -> 0 | N8: =IF(Data!L9-4>0,Data!L9-4,0)+N7 -> 0 | O8: =IF(Data!M9-4>0,Data!M9-4,0)+O7 -> 0 | P8: =IF(Data!N9-4>0,Data!N9-4,0)+P7 -> 0 | T8: =IF(Data!J9>0,Data!J9,0)+T7 -> 0 | U8: =IF(Data!K9>0,Data!K9,0)+U7 -> 0 | V8: =IF(Data!L9>0,Data!L9,0)+V7 -> 0 | W8: =IF(Data!M9>0,Data!M9,0)+W7 -> 0 | X8: =IF(Data!N9>0,Data!N9,0)+X7 -> 0
J9: 46029 | K9: 143 | L9: =IF(Data!J10-4>0,Data!J10-4,0)+L8 -> 0 | M9: =IF(Data!K10-4>0,Data!K10-4,0)+M8 -> 0 | N9: =IF(Data!L10-4>0,Data!L10-4,0)+N8 -> 0 | O9: =IF(Data!M10-4>0,Data!M10-4,0)+O8 -> 0 | P9: =IF(Data!N10-4>0,Data!N10-4,0)+P8 -> 0 | T9: =IF(Data!J10>0,Data!J10,0)+T8 -> 0 | U9: =IF(Data!K10>0,Data!K10,0)+U8 -> 0 | V9: =IF(Data!L10>0,Data!L10,0)+V8 -> 0 | W9: =IF(Data!M10>0,Data!M10,0)+W8 -> 0 | X9: =IF(Data!N10>0,Data!N10,0)+X8 -> 0
J10: 46030 | K10: 143 | L10: =IF(Data!J11-4>0,Data!J11-4,0)+L9 -> 0 | M10: =IF(Data!K11-4>0,Data!K11-4,0)+M9 -> 0 | N10: =IF(Data!L11-4>0,Data!L11-4,0)+N9 -> 0 | O10: =IF(Data!M11-4>0,Data!M11-4,0)+O9 -> 0 | P10: =IF(Data!N11-4>0,Data!N11-4,0)+P9 -> 0 | T10: =IF(Data!J11>0,Data!J11,0)+T9 -> 0 | U10: =IF(Data!K11>0,Data!K11,0)+U9 -> 0 | V10: =IF(Data!L11>0,Data!L11,0)+V9 -> 0 | W10: =IF(Data!M11>0,Data!M11,0)+W9 -> 0 | X10: =IF(Data!N11>0,Data!N11,0)+X9 -> 0
J11: 46031 | K11: 143 | L11: =IF(Data!J12-4>0,Data!J12-4,0)+L10 -> 0 | M11: =IF(Data!K12-4>0,Data!K12-4,0)+M10 -> 0 | N11: =IF(Data!L12-4>0,Data!L12-4,0)+N10 -> 0 | O11: =IF(Data!M12-4>0,Data!M12-4,0)+O10 -> 0 | P11: =IF(Data!N12-4>0,Data!N12-4,0)+P10 -> 0 | T11: =IF(Data!J12>0,Data!J12,0)+T10 -> 0 | U11: =IF(Data!K12>0,Data!K12,0)+U10 -> 0 | V11: =IF(Data!L12>0,Data!L12,0)+V10 -> 0 | W11: =IF(Data!M12>0,Data!M12,0)+W10 -> 0 | X11: =IF(Data!N12>0,Data!N12,0)+X10 -> 0
J12: 46032 | K12: 143 | L12: =IF(Data!J13-4>0,Data!J13-4,0)+L11 -> 0 | M12: =IF(Data!K13-4>0,Data!K13-4,0)+M11 -> 0 | N12: =IF(Data!L13-4>0,Data!L13-4,0)+N11 -> 0 | O12: =IF(Data!M13-4>0,Data!M13-4,0)+O11 -> 0 | P12: =IF(Data!N13-4>0,Data!N13-4,0)+P11 -> 0 | T12: =IF(Data!J13>0,Data!J13,0)+T11 -> 0 | U12: =IF(Data!K13>0,Data!K13,0)+U11 -> 0 | V12: =IF(Data!L13>0,Data!L13,0)+V11 -> 0 | W12: =IF(Data!M13>0,Data!M13,0)+W11 -> 0 | X12: =IF(Data!N13>0,Data!N13,0)+X11 -> 0
J13: 46033 | K13: 143 | L13: =IF(Data!J14-4>0,Data!J14-4,0)+L12 -> 0 | M13: =IF(Data!K14-4>0,Data!K14-4,0)+M12 -> 0 | N13: =IF(Data!L14-4>0,Data!L14-4,0)+N12 -> 0 | O13: =IF(Data!M14-4>0,Data!M14-4,0)+O12 -> 0 | P13: =IF(Data!N14-4>0,Data!N14-4,0)+P12 -> 0 | T13: =IF(Data!J14>0,Data!J14,0)+T12 -> 0 | U13: =IF(Data!K14>0,Data!K14,0)+U12 -> 0 | V13: =IF(Data!L14>0,Data!L14,0)+V12 -> 0 | W13: =IF(Data!M14>0,Data!M14,0)+W12 -> 0 | X13: =IF(Data!N14>0,Data!N14,0)+X12 -> 0
J14: 46034 | K14: 143 | L14: =IF(Data!J15-4>0,Data!J15-4,0)+L13 -> 0 | M14: =IF(Data!K15-4>0,Data!K15-4,0)+M13 -> 0 | N14: =IF(Data!L15-4>0,Data!L15-4,0)+N13 -> 0 | O14: =IF(Data!M15-4>0,Data!M15-4,0)+O13 -> 0 | P14: =IF(Data!N15-4>0,Data!N15-4,0)+P13 -> 0 | T14: =IF(Data!J15>0,Data!J15,0)+T13 -> 0 | U14: =IF(Data!K15>0,Data!K15,0)+U13 -> 0 | V14: =IF(Data!L15>0,Data!L15,0)+V13 -> 0 | W14: =IF(Data!M15>0,Data!M15,0)+W13 -> 0 | X14: =IF(Data!N15>0,Data!N15,0)+X13 -> 0
J15: 46035 | K15: 143 | L15: =IF(Data!J16-4>0,Data!J16-4,0)+L14 -> 0 | M15: =IF(Data!K16-4>0,Data!K16-4,0)+M14 -> 0 | N15: =IF(Data!L16-4>0,Data!L16-4,0)+N14 -> 0 | O15: =IF(Data!M16-4>0,Data!M16-4,0)+O14 -> 0 | P15: =IF(Data!N16-4>0,Data!N16-4,0)+P14 -> 0 | T15: =IF(Data!J16>0,Data!J16,0)+T14 -> 0 | U15: =IF(Data!K16>0,Data!K16,0)+U14 -> 0 | V15: =IF(Data!L16>0,Data!L16,0)+V14 -> 0 | W15: =IF(Data!M16>0,Data!M16,0)+W14 -> 0 | X15: =IF(Data!N16>0,Data!N16,0)+X14 -> 0
... J23: 46043 | K23: 143 | L23: =IF(Data!J24-4>0,Data!J24-4,0)+L22 -> 0 | M23: =IF(Data!K24-4>0,Data!K24-4,0)+M22 -> 0 | N23: =IF(Data!L24-4>0,Data!L24-4,0)+N22 -> 0 | O23: =IF(Data!M24-4>0,Data!M24-4,0)+O22 -> 0 | P23: =IF(Data!N24-4>0,Data!N24-4,0)+P22 -> 0 | T23: =IF(Data!J24>0,Data!J24,0)+T22 -> 0 | U23: =IF(Data!K24>0,Data!K24,0)+U22 -> 0 | V23: =IF(Data!L24>0,Data!L24,0)+V22 -> 0 | W23: =IF(Data!M24>0,Data!M24,0)+W22 -> 0 | X23: =IF(Data!N24>0,Data!N24,0)+X22 -> 0
